Workbook

Sheet Equação
A1: Clínica Vetor (serviços veterinários) | Efeito das transações na Equação do Balanço
A2: Uma linha por movimento: escreve a conta e o valor, com sinal. Transação que mexe em três contas do mesmo lado usa as três linhas. A coluna Check acusa se aquela transação fechou.
A4: Nº | B4: Descrição | C4: ATIVO | E4: = | F4: PASSIVO | H4: + | I4: PATRIMÔNIO LÍQUIDO | K4: Check
C5: conta | D5: valor | F5: conta | G5: valor | I5: conta | J5: valor
A6: 1 | B6: Integralização de capital de R$ 120.000 em dinheiro | E6: = | H6: + | K6: =IF(COUNT(D6:D7,G6:G7,J6:J7)=0,"",IF(SUM(D6:D7)-SUM(G6:G7)-SUM(J6:J7)=0,"✔","✗"))
E7: = | H7: +
A8: 2 | B8: Compra à vista de equipamentos veterinários por R$ 70.000 | E8: = | H8: + | K8: =IF(COUNT(D8:D9,G8:G9,J8:J9)=0,"",IF(SUM(D8:D9)-SUM(G8:G9)-SUM(J8:J9)=0,"✔","✗"))
E9: = | H9: +
A10: 3 | B10: Compra de medicamentos e insumos por R$ 18.000, integralmente a prazo | E10: = | H10: + | K10: =IF(COUNT(D10:D11,G10:G11,J10:J11)=0,"",IF(SUM(D10:D11)-SUM(G10:G11)-SUM(J10:J11)=0,"✔","✗"))
E11: = | H11: +
A12: 4 | B12: Serviços prestados no mês: R$ 52.000, sendo R$ 30.000 à vista e R$ 22.000 a receber de convênios | E12: = | H12: + | K12: =IF(COUNT(D12:D13,G12:G13,J12:J13)=0,"",IF(SUM(D12:D13)-SUM(G12:G13)-SUM(J12:J13)=0,"✔","✗"))
E13: = | H13: +
A14: 5 | B14: Consumo de R$ 11.000 de medicamentos e insumos nos atendimentos do mês | E14: = | H14: + | K14: =IF(COUNT(D14:D15,G14:G15,J14:J15)=0,"",IF(SUM(D14:D15)-SUM(G14:G15)-SUM(J14:J15)=0,"✔","✗"))
E15: = | H15: +
A16: 6 | B16: Pagamento à vista de salários: R$ 16.000 dos veterinários e R$ 8.000 da recepção e do administrativo | E16: = | H16: + | K16: =IF(COUNT(D16:D17,G16:G17,J16:J17)=0,"",IF(SUM(D16:D17)-SUM(G16:G17)-SUM(J16:J17)=0,"✔","✗"))
E17: = | H17: +
A18: 7 | B18: Pagamento de R$ 10.000 a fornecedores | E18: = | H18: + | K18: =IF(COUNT(D18:D19,G18:G19,J18:J19)=0,"",IF(SUM(D18:D19)-SUM(G18:G19)-SUM(J18:J19)=0,"✔","✗"))
E19: = | H19: +
A20: 8 | B20: Recebimento de R$ 9.000 dos convênios | E20: = | H20: + | K20: =IF(COUNT(D20:D21,G20:G21,J20:J21)=0,"",IF(SUM(D20:D21)-SUM(G20:G21)-SUM(J20:J21)=0,"✔","✗"))
E21: = | H21: +

Sheet Plan
B1: Clínica Vetor (serviços veterinários) | D1: Transações, por Número e Descrição
B2: Mês 1 | valores em R$ | D2: Integralização de capital de R$ 120.000 em dinheiro | E2: Compra à vista de equipamentos veterinários por R$ 70.000 | F2: Compra de medicamentos e insumos por R$ 18.000, integralment | G2: Serviços prestados no mês: R$ 52.000, sendo R$ 30.000 à vist | H2: Consumo de R$ 11.000 de medicamentos e insumos nos atendimen | I2: Pagamento à vista de salários: R$ 16.000 dos veterinários e | J2: Pagamento de R$ 10.000 a fornecedores | K2: Recebimento de R$ 9.000 dos convênios
B3: Balanço Patrimonial | C3: Balanço Inicial | D3: 1 | E3: 2 | F3: 3 | G3: 4 | H3: 5 | I3: 6 | J3: 7 | K3: 8 | L3: Balanço Final
B4: ATIVO
B5: Ativo Circulante
B6: Caixa | L6: =C6+SUM(D6:K6) | N6: =IF(COUNT(D6:K6)=0,"",IF(ABS(L6-Gabarito!L6)<0.5,"✔","✗"))
B7: Contas a Receber | L7: =C7+SUM(D7:K7) | N7: =IF(COUNT(D7:K7)=0,"",IF(ABS(L7-Gabarito!L7)<0.5,"✔","✗"))
B8: Estoque de Insumos | L8: =C8+SUM(D8:K8) | N8: =IF(COUNT(D8:K8)=0,"",IF(ABS(L8-Gabarito!L8)<0.5,"✔","✗"))
B9: Ativo Não Circulante
B10: Imobilizado | L10: =C10+SUM(D10:K10) | N10: =IF(COUNT(D10:K10)=0,"",IF(ABS(L10-Gabarito!L10)<0.5,"✔","✗"))
B11: Total do Ativo | C11: =SUM(C6:C10) | D11: =SUM(D6:D10) | E11: =SUM(E6:E10) | F11: =SUM(F6:F10) | G11: =SUM(G6:G10) | H11: =SUM(H6:H10) | I11: =SUM(I6:I10) | J11: =SUM(J6:J10) | ... L11: =SUM(L6:L10)
B12: PASSIVO E PATRIM. LÍQUIDO
B13: Passivo Circulante:
B14: Contas a Pagar | L14: =C14+SUM(D14:K14) | N14: =IF(COUNT(D14:K14)=0,"",IF(ABS(L14-Gabarito!L14)<0.5,"✔","✗"))
B15: Patrimônio Líquido:
B16: Capital Social | L16: =C16+SUM(D16:K16) | N16: =IF(COUNT(D16:K16)=0,"",IF(ABS(L16-Gabarito!L16)<0.5,"✔","✗"))
B17: Lucros Acumulados | L17: =C17+SUM(D17:K17) | N17: =IF(COUNT(D17:K17)=0,"",IF(ABS(L17-Gabarito!L17)<0.5,"✔","✗"))
B18: Total Passivo e Patrim. Líquido | C18: =SUM(C13:C17) | D18: =SUM(D13:D17) | E18: =SUM(E13:E17) | F18: =SUM(F13:F17) | G18: =SUM(G13:G17) | H18: =SUM(H13:H17) | I18: =SUM(I13:I17) | J18: =SUM(J13:J17) | ... L18: =SUM(L13:L17)
B20: Diferença, se houver (tem que dar zero) | C20: =C11-C18 | D20: =D11-D18 | E20: =E11-E18 | F20: =F11-F18 | G20: =G11-G18 | H20: =H11-H18 | I20: =I11-I18 | J20: =J11-J18 | ... L20: =L11-L18 | N20: =IF(L20=0,"✔ fecha","✗ não fecha")
B22: Demonstração do Resultado | D22: 1 | E22: 2 | F22: 3 | G22: 4 | H22: 5 | I22: 6 | J22: 7 | K22: 8 | L22: Mês 1 | N22: Check
B23: Receita de Serviços | L23: =SUM(D23:K23) | N23: =IF(COUNT(D23:K23)=0,"",IF(ABS(L23-Gabarito!L23)<0.5,"✔","✗"))
B24: (-) Custo dos Serviços Prestados | L24: =SUM(D24:K24) | N24: =IF(COUNT(D24:K24)=0,"",IF(ABS(L24-Gabarito!L24)<0.5,"✔","✗"))
B25: (=) Lucro Bruto | D25: =SUM(D23:D24) | E25: =SUM(E23:E24) | F25: =SUM(F23:F24) | G25: =SUM(G23:G24) | H25: =SUM(H23:H24) | I25: =SUM(I23:I24) | J25: =SUM(J23:J24) | K25: =SUM(K23:K24) | L25: =SUM(L23:L24)
B26: (-) Despesas Operacionais | L26: =SUM(D26:K26) | N26: =IF(COUNT(D26:K26)=0,"",IF(ABS(L26-Gabarito!L26)<0.5,"✔","✗"))
B27: (=) EBIT e Lucro Líquido | D27: =SUM(D25:D26) | E27: =SUM(E25:E26) | F27: =SUM(F25:F26) | G27: =SUM(G25:G26) | H27: =SUM(H25:H26) | I27: =SUM(I25:I26) | J27: =SUM(J25:J26) | K27: =SUM(K25:K26) | L27: =SUM(L25:L26)
B29: Demonstração dos Fluxos de Caixa | D29: 1 | E29: 2 | F29: 3 | G29: 4 | H29: 5 | I29: 6 | J29: 7 | K29: 8 | L29: Mês 1
B30: OPERAÇÕES | D30: =SUM(D31:D33) | E30: =SUM(E31:E33) | F30: =SUM(F31:F33) | G30: =SUM(G31:G33) | H30: =SUM(H31:H33) | I30: =SUM(I31:I33) | J30: =SUM(J31:J33) | K30: =SUM(K31:K33) | L30: =SUM(L31:L33)
B31: Recebimentos de Clientes | L31: =SUM(D31:K31) | N31: =IF(COUNT(D31:K31)=0,"",IF(ABS(L31-Gabarito!L31)<0.5,"✔","✗"))
B32: Pagamentos a Fornecedores | L32: =SUM(D32:K32) | N32: =IF(COUNT(D32:K32)=0,"",IF(ABS(L32-Gabarito!L32)<0.5,"✔","✗"))
B33: Pagamentos de Salários e Despesas | L33: =SUM(D33:K33) | N33: =IF(COUNT(D33:K33)=0,"",IF(ABS(L33-Gabarito!L33)<0.5,"✔","✗"))
B34: INVESTIMENTOS | D34: =SUM(D35:D35) | E34: =SUM(E35:E35) | F34: =SUM(F35:F35) | G34: =SUM(G35:G35) | H34: =SUM(H35:H35) | I34: =SUM(I35:I35) | J34: =SUM(J35:J35) | K34: =SUM(K35:K35) | L34: =SUM(L35:L35)
B35: Aquisição de Imobilizado | L35: =SUM(D35:K35) | N35: =IF(COUNT(D35:K35)=0,"",IF(ABS(L35-Gabarito!L35)<0.5,"✔","✗"))
B36: FINANCIAMENTOS | D36: =SUM(D37:D37) | E36: =SUM(E37:E37) | F36: =SUM(F37:F37) | G36: =SUM(G37:G37) | H36: =SUM(H37:H37) | I36: =SUM(I37:I37) | J36: =SUM(J37:J37) | K36: =SUM(K37:K37) | L36: =SUM(L37:L37)
B37: Ingresso de Capital | L37: =SUM(D37:K37) | N37: =IF(COUNT(D37:K37)=0,"",IF(ABS(L37-Gabarito!L37)<0.5,"✔","✗"))
B38: VARIAÇÃO NO CAIXA | D38: =D30+D34+D36 | E38: =E30+E34+E36 | F38: =F30+F34+F36 | G38: =G30+G34+G36 | H38: =H30+H34+H36 | I38: =I30+I34+I36 | J38: =J30+J34+J36 | K38: =K30+K34+K36 | L38: =L30+L34+L36
B39: Saldo inicial de caixa | L39: 0
B40: Saldo final de caixa | L40: =L39+L38
B42: Caixa final da DFC menos Caixa do BP (tem que dar zero) | L42: =L40-L6 | N42: =IF(L42=0,"✔ amarra","✗ não amarra")
B44: Indicadores (automáticos)
B45: Margem bruta | L45: =IF(L23=0,"",L25/L23)
...

Sheet Gabarito
B1: Clínica Vetor (serviços veterinários) | D1: Transações, por Número e Descrição
B2: Mês 1 | valores em R$ | D2: Integralização de capital de R$ 120.000 em dinheiro | E2: Compra à vista de equipamentos veterinários por R$ 70.000 | F2: Compra de medicamentos e insumos por R$ 18.000, integralment | G2: Serviços prestados no mês: R$ 52.000, sendo R$ 30.000 à vist | H2: Consumo de R$ 11.000 de medicamentos e insumos nos atendimen | I2: Pagamento à vista de salários: R$ 16.000 dos veterinários e | J2: Pagamento de R$ 10.000 a fornecedores | K2: Recebimento de R$ 9.000 dos convênios
B3: Balanço Patrimonial | C3: Balanço Inicial | D3: 1 | E3: 2 | F3: 3 | G3: 4 | H3: 5 | I3: 6 | J3: 7 | K3: 8 | L3: Balanço Final
B4: ATIVO
B5: Ativo Circulante
B6: Caixa | D6: 120000 | E6: -70000 | G6: 30000 | I6: -24000 | J6: -10000 | K6: 9000 | L6: =C6+SUM(D6:K6)
B7: Contas a Receber | G7: 22000 | K7: -9000 | L7: =C7+SUM(D7:K7)
B8: Estoque de Insumos | F8: 18000 | H8: -11000 | L8: =C8+SUM(D8:K8)
B9: Ativo Não Circulante
B10: Imobilizado | E10: 70000 | L10: =C10+SUM(D10:K10)
B11: Total do Ativo | C11: =SUM(C6:C10) | D11: =SUM(D6:D10) | E11: =SUM(E6:E10) | F11: =SUM(F6:F10) | G11: =SUM(G6:G10) | H11: =SUM(H6:H10) | I11: =SUM(I6:I10) | J11: =SUM(J6:J10) | ... L11: =SUM(L6:L10)
B12: PASSIVO E PATRIM. LÍQUIDO
B13: Passivo Circulante:
B14: Contas a Pagar | F14: 18000 | J14: -10000 | L14: =C14+SUM(D14:K14)
B15: Patrimônio Líquido:
B16: Capital Social | D16: 120000 | L16: =C16+SUM(D16:K16)
B17: Lucros Acumulados | G17: 52000 | H17: -11000 | I17: -24000 | L17: =C17+SUM(D17:K17)
B18: Total Passivo e Patrim. Líquido | C18: =SUM(C13:C17) | D18: =SUM(D13:D17) | E18: =SUM(E13:E17) | F18: =SUM(F13:F17) | G18: =SUM(G13:G17) | H18: =SUM(H13:H17) | I18: =SUM(I13:I17) | J18: =SUM(J13:J17) | ... L18: =SUM(L13:L17)
B20: Diferença, se houver (tem que dar zero) | C20: =C11-C18 | D20: =D11-D18 | E20: =E11-E18 | F20: =F11-F18 | G20: =G11-G18 | H20: =H11-H18 | I20: =I11-I18 | J20: =J11-J18 | ... L20: =L11-L18
B22: Demonstração do Resultado | D22: 1 | E22: 2 | F22: 3 | G22: 4 | H22: 5 | I22: 6 | J22: 7 | K22: 8 | L22: Mês 1 | N22: Check
B23: Receita de Serviços | G23: 52000 | L23: =SUM(D23:K23)
B24: (-) Custo dos Serviços Prestados | H24: -11000 | I24: -16000 | L24: =SUM(D24:K24)
B25: (=) Lucro Bruto | D25: =SUM(D23:D24) | E25: =SUM(E23:E24) | F25: =SUM(F23:F24) | G25: =SUM(G23:G24) | H25: =SUM(H23:H24) | I25: =SUM(I23:I24) | J25: =SUM(J23:J24) | K25: =SUM(K23:K24) | L25: =SUM(L23:L24)
B26: (-) Despesas Operacionais | I26: -8000 | L26: =SUM(D26:K26)
B27: (=) EBIT e Lucro Líquido | D27: =SUM(D25:D26) | E27: =SUM(E25:E26) | F27: =SUM(F25:F26) | G27: =SUM(G25:G26) | H27: =SUM(H25:H26) | I27: =SUM(I25:I26) | J27: =SUM(J25:J26) | K27: =SUM(K25:K26) | L27: =SUM(L25:L26)
B29: Demonstração dos Fluxos de Caixa | D29: 1 | E29: 2 | F29: 3 | G29: 4 | H29: 5 | I29: 6 | J29: 7 | K29: 8 | L29: Mês 1
B30: OPERAÇÕES | D30: =SUM(D31:D33) | E30: =SUM(E31:E33) | F30: =SUM(F31:F33) | G30: =SUM(G31:G33) | H30: =SUM(H31:H33) | I30: =SUM(I31:I33) | J30: =SUM(J31:J33) | K30: =SUM(K31:K33) | L30: =SUM(L31:L33)
B31: Recebimentos de Clientes | G31: 30000 | K31: 9000 | L31: =SUM(D31:K31)
B32: Pagamentos a Fornecedores | J32: -10000 | L32: =SUM(D32:K32)
B33: Pagamentos de Salários e Despesas | I33: -24000 | L33: =SUM(D33:K33)
B34: INVESTIMENTOS | D34: =SUM(D35:D35) | E34: =SUM(E35:E35) | F34: =SUM(F35:F35) | G34: =SUM(G35:G35) | H34: =SUM(H35:H35) | I34: =SUM(I35:I35) | J34: =SUM(J35:J35) | K34: =SUM(K35:K35) | L34: =SUM(L35:L35)
B35: Aquisição de Imobilizado | E35: -70000 | L35: =SUM(D35:K35)
B36: FINANCIAMENTOS | D36: =SUM(D37:D37) | E36: =SUM(E37:E37) | F36: =SUM(F37:F37) | G36: =SUM(G37:G37) | H36: =SUM(H37:H37) | I36: =SUM(I37:I37) | J36: =SUM(J37:J37) | K36: =SUM(K37:K37) | L36: =SUM(L37:L37)
B37: Ingresso de Capital | D37: 120000 | L37: =SUM(D37:K37)
B38: VARIAÇÃO NO CAIXA | D38: =D30+D34+D36 | E38: =E30+E34+E36 | F38: =F30+F34+F36 | G38: =G30+G34+G36 | H38: =H30+H34+H36 | I38: =I30+I34+I36 | J38: =J30+J34+J36 | K38: =K30+K34+K36 | L38: =L30+L34+L36
B39: Saldo inicial de caixa | L39: 0
B40: Saldo final de caixa | L40: =L39+L38
B42: Caixa final da DFC menos Caixa do BP (tem que dar zero) | L42: =L40-L6
B44: Indicadores (automáticos)
B45: Margem bruta | L45: =IF(L23=0,"",L25/L23)
...

Sheet Gabarito Equação
A1: Clínica Vetor (serviços veterinários) | Efeito das transações na Equação do Balanço
A2: Uma linha por movimento: escreve a conta e o valor, com sinal. Transação que mexe em três contas do mesmo lado usa as três linhas. A coluna Check acusa se aquela transação fechou.
A4: Nº | B4: Descrição | C4: ATIVO | E4: = | F4: PASSIVO | H4: + | I4: PATRIMÔNIO LÍQUIDO | K4: Check
C5: conta | D5: valor | F5: conta | G5: valor | I5: conta | J5: valor
A6: 1 | B6: Integralização de capital de R$ 120.000 em dinheiro | C6: Caixa | D6: 120000 | E6: = | H6: + | I6: Capital Social | J6: 120000 | K6: =IF(COUNT(D6:D7,G6:G7,J6:J7)=0,"",IF(SUM(D6:D7)-SUM(G6:G7)-SUM(J6:J7)=0,"✔","✗"))
E7: = | H7: +
A8: 2 | B8: Compra à vista de equipamentos veterinários por R$ 70.000 | C8: Caixa | D8: -70000 | E8: = | H8: + | K8: =IF(COUNT(D8:D9,G8:G9,J8:J9)=0,"",IF(SUM(D8:D9)-SUM(G8:G9)-SUM(J8:J9)=0,"✔","✗"))
C9: Imobilizado | D9: 70000 | E9: = | H9: +
A10: 3 | B10: Compra de medicamentos e insumos por R$ 18.000, integralmente a prazo | C10: Estoque de Insumos | D10: 18000 | E10: = | F10: Contas a Pagar | G10: 18000 | H10: + | K10: =IF(COUNT(D10:D11,G10:G11,J10:J11)=0,"",IF(SUM(D10:D11)-SUM(G10:G11)-SUM(J10:J11)=0,"✔","✗"))
E11: = | H11: +
A12: 4 | B12: Serviços prestados no mês: R$ 52.000, sendo R$ 30.000 à vista e R$ 22.000 a receber de convênios | C12: Caixa | D12: 30000 | E12: = | H12: + | I12: Lucros Acumulados | J12: 52000 | K12: =IF(COUNT(D12:D13,G12:G13,J12:J13)=0,"",IF(SUM(D12:D13)-SUM(G12:G13)-SUM(J12:J13)=0,"✔","✗"))
C13: Contas a Receber | D13: 22000 | E13: = | H13: +
A14: 5 | B14: Consumo de R$ 11.000 de medicamentos e insumos nos atendimentos do mês | C14: Estoque de Insumos | D14: -11000 | E14: = | H14: + | I14: Lucros Acumulados | J14: -11000 | K14: =IF(COUNT(D14:D15,G14:G15,J14:J15)=0,"",IF(SUM(D14:D15)-SUM(G14:G15)-SUM(J14:J15)=0,"✔","✗"))
E15: = | H15: +
A16: 6 | B16: Pagamento à vista de salários: R$ 16.000 dos veterinários e R$ 8.000 da recepção e do administrativo | C16: Caixa | D16: -24000 | E16: = | H16: + | I16: Lucros Acumulados | J16: -24000 | K16: =IF(COUNT(D16:D17,G16:G17,J16:J17)=0,"",IF(SUM(D16:D17)-SUM(G16:G17)-SUM(J16:J17)=0,"✔","✗"))
E17: = | H17: +
A18: 7 | B18: Pagamento de R$ 10.000 a fornecedores | C18: Caixa | D18: -10000 | E18: = | F18: Contas a Pagar | G18: -10000 | H18: + | K18: =IF(COUNT(D18:D19,G18:G19,J18:J19)=0,"",IF(SUM(D18:D19)-SUM(G18:G19)-SUM(J18:J19)=0,"✔","✗"))
E19: = | H19: +
A20: 8 | B20: Recebimento de R$ 9.000 dos convênios | C20: Caixa | D20: 9000 | E20: = | H20: + | K20: =IF(COUNT(D20:D21,G20:G21,J20:J21)=0,"",IF(SUM(D20:D21)-SUM(G20:G21)-SUM(J20:J21)=0,"✔","✗"))
C21: Contas a Receber | D21: -9000 | E21: = | H21: +
