Workbook

Sheet Equação
A1: Cervejaria Mar Grosso S.A. | Efeito das transações na Equação do Balanço
A2: Uma linha por movimento: escreve a conta e o valor, com sinal. Transação que mexe em três contas do mesmo lado usa as três linhas. A coluna Check acusa se aquela transação fechou.
A4: Nº | B4: Descrição | C4: ATIVO | E4: = | F4: PASSIVO | H4: + | I4: PATRIMÔNIO LÍQUIDO | K4: Check
C5: conta | D5: valor | F5: conta | G5: valor | I5: conta | J5: valor
A6: 1 | B6: Vendas do ano de 520, sendo 380 à vista e 140 a prazo; o custo das mercadorias vendidas foi de 300 | E6: = | H6: + | K6: =IF(COUNT(D6:D8,G6:G8,J6:J8)=0,"",IF(SUM(D6:D8)-SUM(G6:G8)-SUM(J6:J8)=0,"✔","✗"))
E7: = | H7: +
E8: = | H8: +
A9: 2 | B9: Compras de estoque no ano: 330, integralmente a prazo | E9: = | H9: + | K9: =IF(COUNT(D9:D10,G9:G10,J9:J10)=0,"",IF(SUM(D9:D10)-SUM(G9:G10)-SUM(J9:J10)=0,"✔","✗"))
E10: = | H10: +
A11: 3 | B11: Recebimento de 95 de clientes, referente a vendas de anos anteriores | E11: = | H11: + | K11: =IF(COUNT(D11:D12,G11:G12,J11:J12)=0,"",IF(SUM(D11:D12)-SUM(G11:G12)-SUM(J11:J12)=0,"✔","✗"))
E12: = | H12: +
A13: 4 | B13: Pagamento de 310 a fornecedores | E13: = | H13: + | K13: =IF(COUNT(D13:D14,G13:G14,J13:J14)=0,"",IF(SUM(D13:D14)-SUM(G13:G14)-SUM(J13:J14)=0,"✔","✗"))
E14: = | H14: +
A15: 5 | B15: Cliente corporativo adianta 25 por uma encomenda que só será entregue no ano seguinte | E15: = | H15: + | K15: =IF(COUNT(D15:D16,G15:G16,J15:J16)=0,"",IF(SUM(D15:D16)-SUM(G15:G16)-SUM(J15:J16)=0,"✔","✗"))
E16: = | H16: +
A17: 6 | B17: Despesas de vendas e administrativas de 90, pagas à vista | E17: = | H17: + | K17: =IF(COUNT(D17:D18,G17:G18,J17:J18)=0,"",IF(SUM(D17:D18)-SUM(G17:G18)-SUM(J17:J18)=0,"✔","✗"))
E18: = | H18: +
A19: 7 | B19: Depreciação do imobilizado no ano: 30 | E19: = | H19: + | K19: =IF(COUNT(D19:D20,G19:G20,J19:J20)=0,"",IF(SUM(D19:D20)-SUM(G19:G20)-SUM(J19:J20)=0,"✔","✗"))
E20: = | H20: +
A21: 8 | B21: Captação de novo empréstimo bancário de 80 | E21: = | H21: + | K21: =IF(COUNT(D21:D22,G21:G22,J21:J22)=0,"",IF(SUM(D21:D22)-SUM(G21:G22)-SUM(J21:J22)=0,"✔","✗"))
E22: = | H22: +
A23: 9 | B23: Amortização de 50 do principal da dívida e pagamento de 10 de juros do período | E23: = | H23: + | K23: =IF(COUNT(D23:D24,G23:G24,J23:J24)=0,"",IF(SUM(D23:D24)-SUM(G23:G24)-SUM(J23:J24)=0,"✔","✗"))
E24: = | H24: +
A25: 10 | B25: Compra de um novo forno por 120, pagando 45 à vista e 75 em financiamento de longo prazo | E25: = | H25: + | K25: =IF(COUNT(D25:D26,G25:G26,J25:J26)=0,"",IF(SUM(D25:D26)-SUM(G25:G26)-SUM(J25:J26)=0,"✔","✗"))
E26: = | H26: +
A27: 11 | B27: IR e CSLL do ano: 27, sendo 20 pagos à vista e 7 a recolher no ano seguinte | E27: = | H27: + | K27: =IF(COUNT(D27:D28,G27:G28,J27:J28)=0,"",IF(SUM(D27:D28)-SUM(G27:G28)-SUM(J27:J28)=0,"✔","✗"))
E28: = | H28: +
A29: 12 | B29: Dividendos de 25 declarados e pagos em dinheiro | E29: = | H29: + | K29: =IF(COUNT(D29:D30,G29:G30,J29:J30)=0,"",IF(SUM(D29:D30)-SUM(G29:G30)-SUM(J29:J30)=0,"✔","✗"))
E30: = | H30: +

Sheet Plan
B1: Cervejaria Mar Grosso S.A. | Ano 2 | valores em R$ mil | D1: Transações, por Número e Descrição
D2: Vendas do ano de 520, sendo 380 à vista e 140 a prazo; o cus | E2: Compras de estoque no ano: 330, integralmente a prazo | F2: Recebimento de 95 de clientes, referente a vendas de anos an | G2: Pagamento de 310 a fornecedores | H2: Cliente corporativo adianta 25 por uma encomenda que só será | I2: Despesas de vendas e administrativas de 90, pagas à vista | J2: Depreciação do imobilizado no ano: 30 | K2: Captação de novo empréstimo bancário de 80 | L2: Amortização de 50 do principal da dívida e pagamento de 10 d | M2: Compra de um novo forno por 120, pagando 45 à vista e 75 em | N2: IR e CSLL do ano: 27, sendo 20 pagos à vista e 7 a recolher | O2: Dividendos de 25 declarados e pagos em dinheiro
B3: Balanço Patrimonial | C3: Balanço Inicial | D3: 1 | E3: 2 | F3: 3 | G3: 4 | H3: 5 | I3: 6 | J3: 7 | K3: 8 | L3: 9 | M3: 10 | N3: 11 | O3: 12 | P3: Balanço Final
B4: ATIVO
B5: Ativo Circulante
B6: Caixa | C6: 40 | P6: =C6+SUM(D6:O6) | R6: =IF(COUNT(D6:O6)=0,"",IF(ABS(P6-Gabarito!P6)<0.5,"✔","✗"))
B7: Contas a Receber | C7: 60 | P7: =C7+SUM(D7:O7) | R7: =IF(COUNT(D7:O7)=0,"",IF(ABS(P7-Gabarito!P7)<0.5,"✔","✗"))
B8: Estoques | C8: 90 | P8: =C8+SUM(D8:O8) | R8: =IF(COUNT(D8:O8)=0,"",IF(ABS(P8-Gabarito!P8)<0.5,"✔","✗"))
B9: Ativo Não Circulante
B10: Imobilizado | C10: 300 | P10: =C10+SUM(D10:O10) | R10: =IF(COUNT(D10:O10)=0,"",IF(ABS(P10-Gabarito!P10)<0.5,"✔","✗"))
B11: (-) Depreciação Acumulada | C11: -60 | P11: =C11+SUM(D11:O11) | R11: =IF(COUNT(D11:O11)=0,"",IF(ABS(P11-Gabarito!P11)<0.5,"✔","✗"))
B12: Total do Ativo | C12: =SUM(C6:C11) | D12: =SUM(D6:D11) | E12: =SUM(E6:E11) | F12: =SUM(F6:F11) | G12: =SUM(G6:G11) | H12: =SUM(H6:H11) | I12: =SUM(I6:I11) | J12: =SUM(J6:J11) | ... P12: =SUM(P6:P11)
B13: PASSIVO E PATRIM. LÍQUIDO
B14: Passivo Circulante:
B15: Fornecedores | C15: 70 | P15: =C15+SUM(D15:O15) | R15: =IF(COUNT(D15:O15)=0,"",IF(ABS(P15-Gabarito!P15)<0.5,"✔","✗"))
B16: Adiantamentos de Clientes | P16: =C16+SUM(D16:O16) | R16: =IF(COUNT(D16:O16)=0,"",IF(ABS(P16-Gabarito!P16)<0.5,"✔","✗"))
B17: IR a Pagar | P17: =C17+SUM(D17:O17) | R17: =IF(COUNT(D17:O17)=0,"",IF(ABS(P17-Gabarito!P17)<0.5,"✔","✗"))
B18: Empréstimos | C18: 100 | P18: =C18+SUM(D18:O18) | R18: =IF(COUNT(D18:O18)=0,"",IF(ABS(P18-Gabarito!P18)<0.5,"✔","✗"))
B19: Passivo Não Circulante:
B20: Financiamento a Pagar (LP) | P20: =C20+SUM(D20:O20) | R20: =IF(COUNT(D20:O20)=0,"",IF(ABS(P20-Gabarito!P20)<0.5,"✔","✗"))
B21: Patrimônio Líquido:
B22: Capital Social | C22: 200 | P22: =C22+SUM(D22:O22) | R22: =IF(COUNT(D22:O22)=0,"",IF(ABS(P22-Gabarito!P22)<0.5,"✔","✗"))
B23: Lucros Acumulados | C23: 60 | P23: =C23+SUM(D23:O23) | R23: =IF(COUNT(D23:O23)=0,"",IF(ABS(P23-Gabarito!P23)<0.5,"✔","✗"))
B24: Total Passivo e Patrim. Líquido | C24: =SUM(C14:C23) | D24: =SUM(D14:D23) | E24: =SUM(E14:E23) | F24: =SUM(F14:F23) | G24: =SUM(G14:G23) | H24: =SUM(H14:H23) | I24: =SUM(I14:I23) | J24: =SUM(J14:J23) | ... P24: =SUM(P14:P23)
B26: Diferença, se houver (tem que dar zero) | C26: =C12-C24 | D26: =D12-D24 | E26: =E12-E24 | F26: =F12-F24 | G26: =G12-G24 | H26: =H12-H24 | I26: =I12-I24 | J26: =J12-J24 | ... P26: =P12-P24 | R26: =IF(P26=0,"✔ fecha","✗ não fecha")
B28: Demonstração do Resultado | D28: 1 | E28: 2 | F28: 3 | G28: 4 | H28: 5 | I28: 6 | J28: 7 | K28: 8 | L28: 9 | M28: 10 | N28: 11 | O28: 12 | P28: Ano 2 | R28: Check
B29: Receita Líquida de Vendas | P29: =SUM(D29:O29) | R29: =IF(COUNT(D29:O29)=0,"",IF(ABS(P29-Gabarito!P29)<0.5,"✔","✗"))
B30: (-) Custo das Mercadorias Vendidas | P30: =SUM(D30:O30) | R30: =IF(COUNT(D30:O30)=0,"",IF(ABS(P30-Gabarito!P30)<0.5,"✔","✗"))
B31: (=) Lucro Bruto | D31: =SUM(D29:D30) | E31: =SUM(E29:E30) | F31: =SUM(F29:F30) | G31: =SUM(G29:G30) | H31: =SUM(H29:H30) | I31: =SUM(I29:I30) | J31: =SUM(J29:J30) | K31: =SUM(K29:K30) | ... P31: =SUM(P29:P30)
B32: (-) Despesas Operacionais | P32: =SUM(D32:O32) | R32: =IF(COUNT(D32:O32)=0,"",IF(ABS(P32-Gabarito!P32)<0.5,"✔","✗"))
B33: (-) Depreciação | P33: =SUM(D33:O33) | R33: =IF(COUNT(D33:O33)=0,"",IF(ABS(P33-Gabarito!P33)<0.5,"✔","✗"))
B34: (=) EBIT | D34: =SUM(D31:D33) | E34: =SUM(E31:E33) | F34: =SUM(F31:F33) | G34: =SUM(G31:G33) | H34: =SUM(H31:H33) | I34: =SUM(I31:I33) | J34: =SUM(J31:J33) | K34: =SUM(K31:K33) | ... P34: =SUM(P31:P33)
B35: (+/-) Resultado Financeiro | P35: =SUM(D35:O35) | R35: =IF(COUNT(D35:O35)=0,"",IF(ABS(P35-Gabarito!P35)<0.5,"✔","✗"))
B36: (=) LAIR | D36: =SUM(D34:D35) | E36: =SUM(E34:E35) | F36: =SUM(F34:F35) | G36: =SUM(G34:G35) | H36: =SUM(H34:H35) | I36: =SUM(I34:I35) | J36: =SUM(J34:J35) | K36: =SUM(K34:K35) | ... P36: =SUM(P34:P35)
B37: (-) IR e CSLL | P37: =SUM(D37:O37) | R37: =IF(COUNT(D37:O37)=0,"",IF(ABS(P37-Gabarito!P37)<0.5,"✔","✗"))
B38: (=) Lucro Líquido | D38: =SUM(D36:D37) | E38: =SUM(E36:E37) | F38: =SUM(F36:F37) | G38: =SUM(G36:G37) | H38: =SUM(H36:H37) | I38: =SUM(I36:I37) | J38: =SUM(J36:J37) | K38: =SUM(K36:K37) | ... P38: =SUM(P36:P37)
B40: Demonstração dos Fluxos de Caixa | D40: 1 | E40: 2 | F40: 3 | G40: 4 | H40: 5 | I40: 6 | J40: 7 | K40: 8 | L40: 9 | M40: 10 | N40: 11 | O40: 12 | P40: Ano 2
B41: OPERAÇÕES | D41: =SUM(D42:D46) | E41: =SUM(E42:E46) | F41: =SUM(F42:F46) | G41: =SUM(G42:G46) | H41: =SUM(H42:H46) | I41: =SUM(I42:I46) | J41: =SUM(J42:J46) | K41: =SUM(K42:K46) | ... P41: =SUM(P42:P46)
B42: Recebimentos de Clientes | P42: =SUM(D42:O42) | R42: =IF(COUNT(D42:O42)=0,"",IF(ABS(P42-Gabarito!P42)<0.5,"✔","✗"))
B43: Pagamentos a Fornecedores | P43: =SUM(D43:O43) | R43: =IF(COUNT(D43:O43)=0,"",IF(ABS(P43-Gabarito!P43)<0.5,"✔","✗"))
...

Sheet Gabarito
B1: Cervejaria Mar Grosso S.A. | Ano 2 | valores em R$ mil | D1: Transações, por Número e Descrição
D2: Vendas do ano de 520, sendo 380 à vista e 140 a prazo; o cus | E2: Compras de estoque no ano: 330, integralmente a prazo | F2: Recebimento de 95 de clientes, referente a vendas de anos an | G2: Pagamento de 310 a fornecedores | H2: Cliente corporativo adianta 25 por uma encomenda que só será | I2: Despesas de vendas e administrativas de 90, pagas à vista | J2: Depreciação do imobilizado no ano: 30 | K2: Captação de novo empréstimo bancário de 80 | L2: Amortização de 50 do principal da dívida e pagamento de 10 d | M2: Compra de um novo forno por 120, pagando 45 à vista e 75 em | N2: IR e CSLL do ano: 27, sendo 20 pagos à vista e 7 a recolher | O2: Dividendos de 25 declarados e pagos em dinheiro
B3: Balanço Patrimonial | C3: Balanço Inicial | D3: 1 | E3: 2 | F3: 3 | G3: 4 | H3: 5 | I3: 6 | J3: 7 | K3: 8 | L3: 9 | M3: 10 | N3: 11 | O3: 12 | P3: Balanço Final
B4: ATIVO
B5: Ativo Circulante
B6: Caixa | C6: 40 | D6: 380 | F6: 95 | G6: -310 | H6: 25 | I6: -90 | K6: 80 | L6: -60 | M6: -45 | N6: -20 | O6: -25 | P6: =C6+SUM(D6:O6)
B7: Contas a Receber | C7: 60 | D7: 140 | F7: -95 | P7: =C7+SUM(D7:O7)
B8: Estoques | C8: 90 | D8: -300 | E8: 330 | P8: =C8+SUM(D8:O8)
B9: Ativo Não Circulante
B10: Imobilizado | C10: 300 | M10: 120 | P10: =C10+SUM(D10:O10)
B11: (-) Depreciação Acumulada | C11: -60 | J11: -30 | P11: =C11+SUM(D11:O11)
B12: Total do Ativo | C12: =SUM(C6:C11) | D12: =SUM(D6:D11) | E12: =SUM(E6:E11) | F12: =SUM(F6:F11) | G12: =SUM(G6:G11) | H12: =SUM(H6:H11) | I12: =SUM(I6:I11) | J12: =SUM(J6:J11) | ... P12: =SUM(P6:P11)
B13: PASSIVO E PATRIM. LÍQUIDO
B14: Passivo Circulante:
B15: Fornecedores | C15: 70 | E15: 330 | G15: -310 | P15: =C15+SUM(D15:O15)
B16: Adiantamentos de Clientes | H16: 25 | P16: =C16+SUM(D16:O16)
B17: IR a Pagar | N17: 7 | P17: =C17+SUM(D17:O17)
B18: Empréstimos | C18: 100 | K18: 80 | L18: -50 | P18: =C18+SUM(D18:O18)
B19: Passivo Não Circulante:
B20: Financiamento a Pagar (LP) | M20: 75 | P20: =C20+SUM(D20:O20)
B21: Patrimônio Líquido:
B22: Capital Social | C22: 200 | P22: =C22+SUM(D22:O22)
B23: Lucros Acumulados | C23: 60 | D23: 220 | I23: -90 | J23: -30 | L23: -10 | N23: -27 | O23: -25 | P23: =C23+SUM(D23:O23)
B24: Total Passivo e Patrim. Líquido | C24: =SUM(C14:C23) | D24: =SUM(D14:D23) | E24: =SUM(E14:E23) | F24: =SUM(F14:F23) | G24: =SUM(G14:G23) | H24: =SUM(H14:H23) | I24: =SUM(I14:I23) | J24: =SUM(J14:J23) | ... P24: =SUM(P14:P23)
B26: Diferença, se houver (tem que dar zero) | C26: =C12-C24 | D26: =D12-D24 | E26: =E12-E24 | F26: =F12-F24 | G26: =G12-G24 | H26: =H12-H24 | I26: =I12-I24 | J26: =J12-J24 | ... P26: =P12-P24
B28: Demonstração do Resultado | D28: 1 | E28: 2 | F28: 3 | G28: 4 | H28: 5 | I28: 6 | J28: 7 | K28: 8 | L28: 9 | M28: 10 | N28: 11 | O28: 12 | P28: Ano 2 | R28: Check
B29: Receita Líquida de Vendas | D29: 520 | P29: =SUM(D29:O29)
B30: (-) Custo das Mercadorias Vendidas | D30: -300 | P30: =SUM(D30:O30)
B31: (=) Lucro Bruto | D31: =SUM(D29:D30) | E31: =SUM(E29:E30) | F31: =SUM(F29:F30) | G31: =SUM(G29:G30) | H31: =SUM(H29:H30) | I31: =SUM(I29:I30) | J31: =SUM(J29:J30) | K31: =SUM(K29:K30) | ... P31: =SUM(P29:P30)
B32: (-) Despesas Operacionais | I32: -90 | P32: =SUM(D32:O32)
B33: (-) Depreciação | J33: -30 | P33: =SUM(D33:O33)
B34: (=) EBIT | D34: =SUM(D31:D33) | E34: =SUM(E31:E33) | F34: =SUM(F31:F33) | G34: =SUM(G31:G33) | H34: =SUM(H31:H33) | I34: =SUM(I31:I33) | J34: =SUM(J31:J33) | K34: =SUM(K31:K33) | ... P34: =SUM(P31:P33)
B35: (+/-) Resultado Financeiro | L35: -10 | P35: =SUM(D35:O35)
B36: (=) LAIR | D36: =SUM(D34:D35) | E36: =SUM(E34:E35) | F36: =SUM(F34:F35) | G36: =SUM(G34:G35) | H36: =SUM(H34:H35) | I36: =SUM(I34:I35) | J36: =SUM(J34:J35) | K36: =SUM(K34:K35) | ... P36: =SUM(P34:P35)
B37: (-) IR e CSLL | N37: -27 | P37: =SUM(D37:O37)
B38: (=) Lucro Líquido | D38: =SUM(D36:D37) | E38: =SUM(E36:E37) | F38: =SUM(F36:F37) | G38: =SUM(G36:G37) | H38: =SUM(H36:H37) | I38: =SUM(I36:I37) | J38: =SUM(J36:J37) | K38: =SUM(K36:K37) | ... P38: =SUM(P36:P37)
B40: Demonstração dos Fluxos de Caixa | D40: 1 | E40: 2 | F40: 3 | G40: 4 | H40: 5 | I40: 6 | J40: 7 | K40: 8 | L40: 9 | M40: 10 | N40: 11 | O40: 12 | P40: Ano 2
B41: OPERAÇÕES | D41: =SUM(D42:D46) | E41: =SUM(E42:E46) | F41: =SUM(F42:F46) | G41: =SUM(G42:G46) | H41: =SUM(H42:H46) | I41: =SUM(I42:I46) | J41: =SUM(J42:J46) | K41: =SUM(K42:K46) | ... P41: =SUM(P42:P46)
B42: Recebimentos de Clientes | D42: 380 | F42: 95 | H42: 25 | P42: =SUM(D42:O42)
B43: Pagamentos a Fornecedores | G43: -310 | P43: =SUM(D43:O43)
...

Sheet Gabarito Equação
A1: Cervejaria Mar Grosso S.A. | Efeito das transações na Equação do Balanço
A2: Uma linha por movimento: escreve a conta e o valor, com sinal. Transação que mexe em três contas do mesmo lado usa as três linhas. A coluna Check acusa se aquela transação fechou.
A4: Nº | B4: Descrição | C4: ATIVO | E4: = | F4: PASSIVO | H4: + | I4: PATRIMÔNIO LÍQUIDO | K4: Check
C5: conta | D5: valor | F5: conta | G5: valor | I5: conta | J5: valor
A6: 1 | B6: Vendas do ano de 520, sendo 380 à vista e 140 a prazo; o custo das mercadorias vendidas foi de 300 | C6: Caixa | D6: 380 | E6: = | H6: + | I6: Lucros Acumulados | J6: 220 | K6: =IF(COUNT(D6:D8,G6:G8,J6:J8)=0,"",IF(SUM(D6:D8)-SUM(G6:G8)-SUM(J6:J8)=0,"✔","✗"))
C7: Contas a Receber | D7: 140 | E7: = | H7: +
C8: Estoques | D8: -300 | E8: = | H8: +
A9: 2 | B9: Compras de estoque no ano: 330, integralmente a prazo | C9: Estoques | D9: 330 | E9: = | F9: Fornecedores | G9: 330 | H9: + | K9: =IF(COUNT(D9:D10,G9:G10,J9:J10)=0,"",IF(SUM(D9:D10)-SUM(G9:G10)-SUM(J9:J10)=0,"✔","✗"))
E10: = | H10: +
A11: 3 | B11: Recebimento de 95 de clientes, referente a vendas de anos anteriores | C11: Caixa | D11: 95 | E11: = | H11: + | K11: =IF(COUNT(D11:D12,G11:G12,J11:J12)=0,"",IF(SUM(D11:D12)-SUM(G11:G12)-SUM(J11:J12)=0,"✔","✗"))
C12: Contas a Receber | D12: -95 | E12: = | H12: +
A13: 4 | B13: Pagamento de 310 a fornecedores | C13: Caixa | D13: -310 | E13: = | F13: Fornecedores | G13: -310 | H13: + | K13: =IF(COUNT(D13:D14,G13:G14,J13:J14)=0,"",IF(SUM(D13:D14)-SUM(G13:G14)-SUM(J13:J14)=0,"✔","✗"))
E14: = | H14: +
A15: 5 | B15: Cliente corporativo adianta 25 por uma encomenda que só será entregue no ano seguinte | C15: Caixa | D15: 25 | E15: = | F15: Adiantamentos de Clientes | G15: 25 | H15: + | K15: =IF(COUNT(D15:D16,G15:G16,J15:J16)=0,"",IF(SUM(D15:D16)-SUM(G15:G16)-SUM(J15:J16)=0,"✔","✗"))
E16: = | H16: +
A17: 6 | B17: Despesas de vendas e administrativas de 90, pagas à vista | C17: Caixa | D17: -90 | E17: = | H17: + | I17: Lucros Acumulados | J17: -90 | K17: =IF(COUNT(D17:D18,G17:G18,J17:J18)=0,"",IF(SUM(D17:D18)-SUM(G17:G18)-SUM(J17:J18)=0,"✔","✗"))
E18: = | H18: +
A19: 7 | B19: Depreciação do imobilizado no ano: 30 | C19: (-) Depreciação Acumulada | D19: -30 | E19: = | H19: + | I19: Lucros Acumulados | J19: -30 | K19: =IF(COUNT(D19:D20,G19:G20,J19:J20)=0,"",IF(SUM(D19:D20)-SUM(G19:G20)-SUM(J19:J20)=0,"✔","✗"))
E20: = | H20: +
A21: 8 | B21: Captação de novo empréstimo bancário de 80 | C21: Caixa | D21: 80 | E21: = | F21: Empréstimos | G21: 80 | H21: + | K21: =IF(COUNT(D21:D22,G21:G22,J21:J22)=0,"",IF(SUM(D21:D22)-SUM(G21:G22)-SUM(J21:J22)=0,"✔","✗"))
E22: = | H22: +
A23: 9 | B23: Amortização de 50 do principal da dívida e pagamento de 10 de juros do período | C23: Caixa | D23: -60 | E23: = | F23: Empréstimos | G23: -50 | H23: + | I23: Lucros Acumulados | J23: -10 | K23: =IF(COUNT(D23:D24,G23:G24,J23:J24)=0,"",IF(SUM(D23:D24)-SUM(G23:G24)-SUM(J23:J24)=0,"✔","✗"))
E24: = | H24: +
A25: 10 | B25: Compra de um novo forno por 120, pagando 45 à vista e 75 em financiamento de longo prazo | C25: Caixa | D25: -45 | E25: = | F25: Financiamento a Pagar (LP) | G25: 75 | H25: + | K25: =IF(COUNT(D25:D26,G25:G26,J25:J26)=0,"",IF(SUM(D25:D26)-SUM(G25:G26)-SUM(J25:J26)=0,"✔","✗"))
C26: Imobilizado | D26: 120 | E26: = | H26: +
A27: 11 | B27: IR e CSLL do ano: 27, sendo 20 pagos à vista e 7 a recolher no ano seguinte | C27: Caixa | D27: -20 | E27: = | F27: IR a Pagar | G27: 7 | H27: + | I27: Lucros Acumulados | J27: -27 | K27: =IF(COUNT(D27:D28,G27:G28,J27:J28)=0,"",IF(SUM(D27:D28)-SUM(G27:G28)-SUM(J27:J28)=0,"✔","✗"))
E28: = | H28: +
A29: 12 | B29: Dividendos de 25 declarados e pagos em dinheiro | C29: Caixa | D29: -25 | E29: = | H29: + | I29: Lucros Acumulados | J29: -25 | K29: =IF(COUNT(D29:D30,G29:G30,J29:J30)=0,"",IF(SUM(D29:D30)-SUM(G29:G30)-SUM(J29:J30)=0,"✔","✗"))
E30: = | H30: +
