Workbook

Sheet Equação
A1: Metalúrgica Pilar S.A. | Efeito das transações na Equação do Balanço
A2: Uma linha por movimento: escreve a conta e o valor, com sinal. Transação que mexe em três contas do mesmo lado usa as três linhas. A coluna Check acusa se aquela transação fechou.
A4: Nº | B4: Descrição | C4: ATIVO | E4: = | F4: PASSIVO | H4: + | I4: PATRIMÔNIO LÍQUIDO | K4: Check
C5: conta | D5: valor | F5: conta | G5: valor | I5: conta | J5: valor
A6: 1 | B6: Compra de matéria-prima por 260, sendo 60 à vista e 200 a prazo | E6: = | H6: + | K6: =IF(COUNT(D6:D7,G6:G7,J6:J7)=0,"",IF(SUM(D6:D7)-SUM(G6:G7)-SUM(J6:J7)=0,"✔","✗"))
E7: = | H7: +
A8: 2 | B8: Requisição de 250 de matéria-prima para a linha de produção | E8: = | H8: + | K8: =IF(COUNT(D8:D9,G8:G9,J8:J9)=0,"",IF(SUM(D8:D9)-SUM(G8:G9)-SUM(J8:J9)=0,"✔","✗"))
E9: = | H9: +
A10: 3 | B10: Folha da fábrica do ano, 180, apropriada ao custo de produção | E10: = | H10: + | K10: =IF(COUNT(D10:D11,G10:G11,J10:J11)=0,"",IF(SUM(D10:D11)-SUM(G10:G11)-SUM(J10:J11)=0,"✔","✗"))
E11: = | H11: +
A12: 4 | B12: Pagamento de salários: 190 em dinheiro, incluindo os 20 devidos do ano anterior | E12: = | H12: + | K12: =IF(COUNT(D12:D13,G12:G13,J12:J13)=0,"",IF(SUM(D12:D13)-SUM(G12:G13)-SUM(J12:J13)=0,"✔","✗"))
E13: = | H13: +
A14: 5 | B14: Depreciação do ano: 40, sendo 30 das máquinas da fábrica e 10 dos móveis do escritório | E14: = | H14: + | K14: =IF(COUNT(D14:D15,G14:G15,J14:J15)=0,"",IF(SUM(D14:D15)-SUM(G14:G15)-SUM(J14:J15)=0,"✔","✗"))
E15: = | H15: +
A16: 6 | B16: Produção concluída no ano e transferida para produtos acabados: 470 | E16: = | H16: + | K16: =IF(COUNT(D16:D17,G16:G17,J16:J17)=0,"",IF(SUM(D16:D17)-SUM(G16:G17)-SUM(J16:J17)=0,"✔","✗"))
E17: = | H17: +
A18: 7 | B18: Vendas do ano: 700, sendo 450 à vista e 250 a prazo; o custo dos produtos vendidos foi 480 | E18: = | H18: + | K18: =IF(COUNT(D18:D20,G18:G20,J18:J20)=0,"",IF(SUM(D18:D20)-SUM(G18:G20)-SUM(J18:J20)=0,"✔","✗"))
E19: = | H19: +
E20: = | H20: +
A21: 8 | B21: Recebimento de 210 de clientes, referente a vendas de anos anteriores | E21: = | H21: + | K21: =IF(COUNT(D21:D22,G21:G22,J21:J22)=0,"",IF(SUM(D21:D22)-SUM(G21:G22)-SUM(J21:J22)=0,"✔","✗"))
E22: = | H22: +
A23: 9 | B23: Pagamento de 230 a fornecedores | E23: = | H23: + | K23: =IF(COUNT(D23:D24,G23:G24,J23:J24)=0,"",IF(SUM(D23:D24)-SUM(G23:G24)-SUM(J23:J24)=0,"✔","✗"))
E24: = | H24: +
A25: 10 | B25: Despesas comerciais e administrativas do ano: 90, pagas à vista | E25: = | H25: + | K25: =IF(COUNT(D25:D26,G25:G26,J25:J26)=0,"",IF(SUM(D25:D26)-SUM(G25:G26)-SUM(J25:J26)=0,"✔","✗"))
E26: = | H26: +
A27: 11 | B27: Compra à vista de uma nova prensa por 60 | E27: = | H27: + | K27: =IF(COUNT(D27:D28,G27:G28,J27:J28)=0,"",IF(SUM(D27:D28)-SUM(G27:G28)-SUM(J27:J28)=0,"✔","✗"))
E28: = | H28: +
A29: 12 | B29: Pagamento de 20 de juros e amortização de 50 do principal da dívida | E29: = | H29: + | K29: =IF(COUNT(D29:D30,G29:G30,J29:J30)=0,"",IF(SUM(D29:D30)-SUM(G29:G30)-SUM(J29:J30)=0,"✔","✗"))
E30: = | H30: +
A31: 13 | B31: IR e CSLL do ano: 30, pagos integralmente à vista | E31: = | H31: + | K31: =IF(COUNT(D31:D32,G31:G32,J31:J32)=0,"",IF(SUM(D31:D32)-SUM(G31:G32)-SUM(J31:J32)=0,"✔","✗"))
E32: = | H32: +
A33: 14 | B33: Dividendos de 25 declarados e pagos em dinheiro | E33: = | H33: + | K33: =IF(COUNT(D33:D34,G33:G34,J33:J34)=0,"",IF(SUM(D33:D34)-SUM(G33:G34)-SUM(J33:J34)=0,"✔","✗"))
E34: = | H34: +

Sheet Plan
B1: Metalúrgica Pilar S.A. | D1: Transações, por Número e Descrição
B2: Ano 3 | valores em R$ mil | D2: Compra de matéria-prima por 260, sendo 60 à vista e 200 a pr | E2: Requisição de 250 de matéria-prima para a linha de produção | F2: Folha da fábrica do ano, 180, apropriada ao custo de produçã | G2: Pagamento de salários: 190 em dinheiro, incluindo os 20 devi | H2: Depreciação do ano: 40, sendo 30 das máquinas da fábrica e 1 | I2: Produção concluída no ano e transferida para produtos acabad | J2: Vendas do ano: 700, sendo 450 à vista e 250 a prazo; o custo | K2: Recebimento de 210 de clientes, referente a vendas de anos a | L2: Pagamento de 230 a fornecedores | M2: Despesas comerciais e administrativas do ano: 90, pagas à vi | N2: Compra à vista de uma nova prensa por 60 | O2: Pagamento de 20 de juros e amortização de 50 do principal da | P2: IR e CSLL do ano: 30, pagos integralmente à vista | Q2: Dividendos de 25 declarados e pagos em dinheiro
B3: Balanço Patrimonial | C3: Balanço Inicial | D3: 1 | E3: 2 | F3: 3 | G3: 4 | H3: 5 | I3: 6 | J3: 7 | K3: 8 | L3: 9 | M3: 10 | N3: 11 | O3: 12 | P3: 13 | Q3: 14 | R3: Balanço Final
B4: ATIVO
B5: Ativo Circulante
B6: Caixa | C6: 110 | R6: =C6+SUM(D6:Q6) | T6: =IF(COUNT(D6:Q6)=0,"",IF(ABS(R6-Gabarito!R6)<0.5,"✔","✗"))
B7: Contas a Receber | C7: 80 | R7: =C7+SUM(D7:Q7) | T7: =IF(COUNT(D7:Q7)=0,"",IF(ABS(R7-Gabarito!R7)<0.5,"✔","✗"))
B8: Estoque de Matéria-Prima | C8: 40 | R8: =C8+SUM(D8:Q8) | T8: =IF(COUNT(D8:Q8)=0,"",IF(ABS(R8-Gabarito!R8)<0.5,"✔","✗"))
B9: Produtos em Elaboração | C9: 20 | R9: =C9+SUM(D9:Q9) | T9: =IF(COUNT(D9:Q9)=0,"",IF(ABS(R9-Gabarito!R9)<0.5,"✔","✗"))
B10: Produtos Acabados | C10: 60 | R10: =C10+SUM(D10:Q10) | T10: =IF(COUNT(D10:Q10)=0,"",IF(ABS(R10-Gabarito!R10)<0.5,"✔","✗"))
B11: Ativo Não Circulante
B12: Imobilizado | C12: 400 | R12: =C12+SUM(D12:Q12) | T12: =IF(COUNT(D12:Q12)=0,"",IF(ABS(R12-Gabarito!R12)<0.5,"✔","✗"))
B13: (-) Depreciação Acumulada | C13: -120 | R13: =C13+SUM(D13:Q13) | T13: =IF(COUNT(D13:Q13)=0,"",IF(ABS(R13-Gabarito!R13)<0.5,"✔","✗"))
B14: Total do Ativo | C14: =SUM(C6:C13) | D14: =SUM(D6:D13) | E14: =SUM(E6:E13) | F14: =SUM(F6:F13) | G14: =SUM(G6:G13) | H14: =SUM(H6:H13) | I14: =SUM(I6:I13) | J14: =SUM(J6:J13) | ... R14: =SUM(R6:R13)
B15: PASSIVO E PATRIM. LÍQUIDO
B16: Passivo Circulante:
B17: Fornecedores | C17: 90 | R17: =C17+SUM(D17:Q17) | T17: =IF(COUNT(D17:Q17)=0,"",IF(ABS(R17-Gabarito!R17)<0.5,"✔","✗"))
B18: Salários a Pagar | C18: 20 | R18: =C18+SUM(D18:Q18) | T18: =IF(COUNT(D18:Q18)=0,"",IF(ABS(R18-Gabarito!R18)<0.5,"✔","✗"))
B19: Empréstimos | C19: 150 | R19: =C19+SUM(D19:Q19) | T19: =IF(COUNT(D19:Q19)=0,"",IF(ABS(R19-Gabarito!R19)<0.5,"✔","✗"))
B20: Patrimônio Líquido:
B21: Capital Social | C21: 260 | R21: =C21+SUM(D21:Q21) | T21: =IF(COUNT(D21:Q21)=0,"",IF(ABS(R21-Gabarito!R21)<0.5,"✔","✗"))
B22: Lucros Acumulados | C22: 70 | R22: =C22+SUM(D22:Q22) | T22: =IF(COUNT(D22:Q22)=0,"",IF(ABS(R22-Gabarito!R22)<0.5,"✔","✗"))
B23: Total Passivo e Patrim. Líquido | C23: =SUM(C16:C22) | D23: =SUM(D16:D22) | E23: =SUM(E16:E22) | F23: =SUM(F16:F22) | G23: =SUM(G16:G22) | H23: =SUM(H16:H22) | I23: =SUM(I16:I22) | J23: =SUM(J16:J22) | ... R23: =SUM(R16:R22)
B25: Diferença, se houver (tem que dar zero) | C25: =C14-C23 | D25: =D14-D23 | E25: =E14-E23 | F25: =F14-F23 | G25: =G14-G23 | H25: =H14-H23 | I25: =I14-I23 | J25: =J14-J23 | ... R25: =R14-R23 | T25: =IF(R25=0,"✔ fecha","✗ não fecha")
B27: Demonstração do Resultado | D27: 1 | E27: 2 | F27: 3 | G27: 4 | H27: 5 | I27: 6 | J27: 7 | K27: 8 | L27: 9 | M27: 10 | N27: 11 | O27: 12 | P27: 13 | Q27: 14 | R27: Ano 3 | T27: Check
B28: Receita Líquida de Vendas | R28: =SUM(D28:Q28) | T28: =IF(COUNT(D28:Q28)=0,"",IF(ABS(R28-Gabarito!R28)<0.5,"✔","✗"))
B29: (-) Custo dos Produtos Vendidos | R29: =SUM(D29:Q29) | T29: =IF(COUNT(D29:Q29)=0,"",IF(ABS(R29-Gabarito!R29)<0.5,"✔","✗"))
B30: (=) Lucro Bruto | D30: =SUM(D28:D29) | E30: =SUM(E28:E29) | F30: =SUM(F28:F29) | G30: =SUM(G28:G29) | H30: =SUM(H28:H29) | I30: =SUM(I28:I29) | J30: =SUM(J28:J29) | K30: =SUM(K28:K29) | ... R30: =SUM(R28:R29)
B31: (-) Despesas Comerciais e Administrativas | R31: =SUM(D31:Q31) | T31: =IF(COUNT(D31:Q31)=0,"",IF(ABS(R31-Gabarito!R31)<0.5,"✔","✗"))
B32: (-) Depreciação (administrativa) | R32: =SUM(D32:Q32) | T32: =IF(COUNT(D32:Q32)=0,"",IF(ABS(R32-Gabarito!R32)<0.5,"✔","✗"))
B33: (=) EBIT | D33: =SUM(D30:D32) | E33: =SUM(E30:E32) | F33: =SUM(F30:F32) | G33: =SUM(G30:G32) | H33: =SUM(H30:H32) | I33: =SUM(I30:I32) | J33: =SUM(J30:J32) | K33: =SUM(K30:K32) | ... R33: =SUM(R30:R32)
B34: (+/-) Resultado Financeiro | R34: =SUM(D34:Q34) | T34: =IF(COUNT(D34:Q34)=0,"",IF(ABS(R34-Gabarito!R34)<0.5,"✔","✗"))
B35: (=) LAIR | D35: =SUM(D33:D34) | E35: =SUM(E33:E34) | F35: =SUM(F33:F34) | G35: =SUM(G33:G34) | H35: =SUM(H33:H34) | I35: =SUM(I33:I34) | J35: =SUM(J33:J34) | K35: =SUM(K33:K34) | ... R35: =SUM(R33:R34)
B36: (-) IR e CSLL | R36: =SUM(D36:Q36) | T36: =IF(COUNT(D36:Q36)=0,"",IF(ABS(R36-Gabarito!R36)<0.5,"✔","✗"))
B37: (=) Lucro Líquido | D37: =SUM(D35:D36) | E37: =SUM(E35:E36) | F37: =SUM(F35:F36) | G37: =SUM(G35:G36) | H37: =SUM(H35:H36) | I37: =SUM(I35:I36) | J37: =SUM(J35:J36) | K37: =SUM(K35:K36) | ... R37: =SUM(R35:R36)
B39: Demonstração dos Fluxos de Caixa | D39: 1 | E39: 2 | F39: 3 | G39: 4 | H39: 5 | I39: 6 | J39: 7 | K39: 8 | L39: 9 | M39: 10 | N39: 11 | O39: 12 | P39: 13 | Q39: 14 | R39: Ano 3
B40: OPERAÇÕES | D40: =SUM(D41:D46) | E40: =SUM(E41:E46) | F40: =SUM(F41:F46) | G40: =SUM(G41:G46) | H40: =SUM(H41:H46) | I40: =SUM(I41:I46) | J40: =SUM(J41:J46) | K40: =SUM(K41:K46) | ... R40: =SUM(R41:R46)
B41: Recebimentos de Clientes | R41: =SUM(D41:Q41) | T41: =IF(COUNT(D41:Q41)=0,"",IF(ABS(R41-Gabarito!R41)<0.5,"✔","✗"))
B42: Pagamentos a Fornecedores | R42: =SUM(D42:Q42) | T42: =IF(COUNT(D42:Q42)=0,"",IF(ABS(R42-Gabarito!R42)<0.5,"✔","✗"))
B43: Pagamentos de Salários | R43: =SUM(D43:Q43) | T43: =IF(COUNT(D43:Q43)=0,"",IF(ABS(R43-Gabarito!R43)<0.5,"✔","✗"))
...

Sheet Gabarito
B1: Metalúrgica Pilar S.A. | D1: Transações, por Número e Descrição
B2: Ano 3 | valores em R$ mil | D2: Compra de matéria-prima por 260, sendo 60 à vista e 200 a pr | E2: Requisição de 250 de matéria-prima para a linha de produção | F2: Folha da fábrica do ano, 180, apropriada ao custo de produçã | G2: Pagamento de salários: 190 em dinheiro, incluindo os 20 devi | H2: Depreciação do ano: 40, sendo 30 das máquinas da fábrica e 1 | I2: Produção concluída no ano e transferida para produtos acabad | J2: Vendas do ano: 700, sendo 450 à vista e 250 a prazo; o custo | K2: Recebimento de 210 de clientes, referente a vendas de anos a | L2: Pagamento de 230 a fornecedores | M2: Despesas comerciais e administrativas do ano: 90, pagas à vi | N2: Compra à vista de uma nova prensa por 60 | O2: Pagamento de 20 de juros e amortização de 50 do principal da | P2: IR e CSLL do ano: 30, pagos integralmente à vista | Q2: Dividendos de 25 declarados e pagos em dinheiro
B3: Balanço Patrimonial | C3: Balanço Inicial | D3: 1 | E3: 2 | F3: 3 | G3: 4 | H3: 5 | I3: 6 | J3: 7 | K3: 8 | L3: 9 | M3: 10 | N3: 11 | O3: 12 | P3: 13 | Q3: 14 | R3: Balanço Final
B4: ATIVO
B5: Ativo Circulante
B6: Caixa | C6: 110 | D6: -60 | G6: -190 | J6: 450 | K6: 210 | L6: -230 | M6: -90 | N6: -60 | O6: -70 | P6: -30 | Q6: -25 | R6: =C6+SUM(D6:Q6)
B7: Contas a Receber | C7: 80 | J7: 250 | K7: -210 | R7: =C7+SUM(D7:Q7)
B8: Estoque de Matéria-Prima | C8: 40 | D8: 260 | E8: -250 | R8: =C8+SUM(D8:Q8)
B9: Produtos em Elaboração | C9: 20 | E9: 250 | F9: 180 | H9: 30 | I9: -470 | R9: =C9+SUM(D9:Q9)
B10: Produtos Acabados | C10: 60 | I10: 470 | J10: -480 | R10: =C10+SUM(D10:Q10)
B11: Ativo Não Circulante
B12: Imobilizado | C12: 400 | N12: 60 | R12: =C12+SUM(D12:Q12)
B13: (-) Depreciação Acumulada | C13: -120 | H13: -40 | R13: =C13+SUM(D13:Q13)
B14: Total do Ativo | C14: =SUM(C6:C13) | D14: =SUM(D6:D13) | E14: =SUM(E6:E13) | F14: =SUM(F6:F13) | G14: =SUM(G6:G13) | H14: =SUM(H6:H13) | I14: =SUM(I6:I13) | J14: =SUM(J6:J13) | ... R14: =SUM(R6:R13)
B15: PASSIVO E PATRIM. LÍQUIDO
B16: Passivo Circulante:
B17: Fornecedores | C17: 90 | D17: 200 | L17: -230 | R17: =C17+SUM(D17:Q17)
B18: Salários a Pagar | C18: 20 | F18: 180 | G18: -190 | R18: =C18+SUM(D18:Q18)
B19: Empréstimos | C19: 150 | O19: -50 | R19: =C19+SUM(D19:Q19)
B20: Patrimônio Líquido:
B21: Capital Social | C21: 260 | R21: =C21+SUM(D21:Q21)
B22: Lucros Acumulados | C22: 70 | H22: -10 | J22: 220 | M22: -90 | O22: -20 | P22: -30 | Q22: -25 | R22: =C22+SUM(D22:Q22)
B23: Total Passivo e Patrim. Líquido | C23: =SUM(C16:C22) | D23: =SUM(D16:D22) | E23: =SUM(E16:E22) | F23: =SUM(F16:F22) | G23: =SUM(G16:G22) | H23: =SUM(H16:H22) | I23: =SUM(I16:I22) | J23: =SUM(J16:J22) | ... R23: =SUM(R16:R22)
B25: Diferença, se houver (tem que dar zero) | C25: =C14-C23 | D25: =D14-D23 | E25: =E14-E23 | F25: =F14-F23 | G25: =G14-G23 | H25: =H14-H23 | I25: =I14-I23 | J25: =J14-J23 | ... R25: =R14-R23
B27: Demonstração do Resultado | D27: 1 | E27: 2 | F27: 3 | G27: 4 | H27: 5 | I27: 6 | J27: 7 | K27: 8 | L27: 9 | M27: 10 | N27: 11 | O27: 12 | P27: 13 | Q27: 14 | R27: Ano 3 | T27: Check
B28: Receita Líquida de Vendas | J28: 700 | R28: =SUM(D28:Q28)
B29: (-) Custo dos Produtos Vendidos | J29: -480 | R29: =SUM(D29:Q29)
B30: (=) Lucro Bruto | D30: =SUM(D28:D29) | E30: =SUM(E28:E29) | F30: =SUM(F28:F29) | G30: =SUM(G28:G29) | H30: =SUM(H28:H29) | I30: =SUM(I28:I29) | J30: =SUM(J28:J29) | K30: =SUM(K28:K29) | ... R30: =SUM(R28:R29)
B31: (-) Despesas Comerciais e Administrativas | M31: -90 | R31: =SUM(D31:Q31)
B32: (-) Depreciação (administrativa) | H32: -10 | R32: =SUM(D32:Q32)
B33: (=) EBIT | D33: =SUM(D30:D32) | E33: =SUM(E30:E32) | F33: =SUM(F30:F32) | G33: =SUM(G30:G32) | H33: =SUM(H30:H32) | I33: =SUM(I30:I32) | J33: =SUM(J30:J32) | K33: =SUM(K30:K32) | ... R33: =SUM(R30:R32)
B34: (+/-) Resultado Financeiro | O34: -20 | R34: =SUM(D34:Q34)
B35: (=) LAIR | D35: =SUM(D33:D34) | E35: =SUM(E33:E34) | F35: =SUM(F33:F34) | G35: =SUM(G33:G34) | H35: =SUM(H33:H34) | I35: =SUM(I33:I34) | J35: =SUM(J33:J34) | K35: =SUM(K33:K34) | ... R35: =SUM(R33:R34)
B36: (-) IR e CSLL | P36: -30 | R36: =SUM(D36:Q36)
B37: (=) Lucro Líquido | D37: =SUM(D35:D36) | E37: =SUM(E35:E36) | F37: =SUM(F35:F36) | G37: =SUM(G35:G36) | H37: =SUM(H35:H36) | I37: =SUM(I35:I36) | J37: =SUM(J35:J36) | K37: =SUM(K35:K36) | ... R37: =SUM(R35:R36)
B39: Demonstração dos Fluxos de Caixa | D39: 1 | E39: 2 | F39: 3 | G39: 4 | H39: 5 | I39: 6 | J39: 7 | K39: 8 | L39: 9 | M39: 10 | N39: 11 | O39: 12 | P39: 13 | Q39: 14 | R39: Ano 3
B40: OPERAÇÕES | D40: =SUM(D41:D46) | E40: =SUM(E41:E46) | F40: =SUM(F41:F46) | G40: =SUM(G41:G46) | H40: =SUM(H41:H46) | I40: =SUM(I41:I46) | J40: =SUM(J41:J46) | K40: =SUM(K41:K46) | ... R40: =SUM(R41:R46)
B41: Recebimentos de Clientes | J41: 450 | K41: 210 | R41: =SUM(D41:Q41)
B42: Pagamentos a Fornecedores | D42: -60 | L42: -230 | R42: =SUM(D42:Q42)
B43: Pagamentos de Salários | G43: -190 | R43: =SUM(D43:Q43)
...

Sheet Gabarito Equação
A1: Metalúrgica Pilar S.A. | Efeito das transações na Equação do Balanço
A2: Uma linha por movimento: escreve a conta e o valor, com sinal. Transação que mexe em três contas do mesmo lado usa as três linhas. A coluna Check acusa se aquela transação fechou.
A4: Nº | B4: Descrição | C4: ATIVO | E4: = | F4: PASSIVO | H4: + | I4: PATRIMÔNIO LÍQUIDO | K4: Check
C5: conta | D5: valor | F5: conta | G5: valor | I5: conta | J5: valor
A6: 1 | B6: Compra de matéria-prima por 260, sendo 60 à vista e 200 a prazo | C6: Caixa | D6: -60 | E6: = | F6: Fornecedores | G6: 200 | H6: + | K6: =IF(COUNT(D6:D7,G6:G7,J6:J7)=0,"",IF(SUM(D6:D7)-SUM(G6:G7)-SUM(J6:J7)=0,"✔","✗"))
C7: Estoque de Matéria-Prima | D7: 260 | E7: = | H7: +
A8: 2 | B8: Requisição de 250 de matéria-prima para a linha de produção | C8: Estoque de Matéria-Prima | D8: -250 | E8: = | H8: + | K8: =IF(COUNT(D8:D9,G8:G9,J8:J9)=0,"",IF(SUM(D8:D9)-SUM(G8:G9)-SUM(J8:J9)=0,"✔","✗"))
C9: Produtos em Elaboração | D9: 250 | E9: = | H9: +
A10: 3 | B10: Folha da fábrica do ano, 180, apropriada ao custo de produção | C10: Produtos em Elaboração | D10: 180 | E10: = | F10: Salários a Pagar | G10: 180 | H10: + | K10: =IF(COUNT(D10:D11,G10:G11,J10:J11)=0,"",IF(SUM(D10:D11)-SUM(G10:G11)-SUM(J10:J11)=0,"✔","✗"))
E11: = | H11: +
A12: 4 | B12: Pagamento de salários: 190 em dinheiro, incluindo os 20 devidos do ano anterior | C12: Caixa | D12: -190 | E12: = | F12: Salários a Pagar | G12: -190 | H12: + | K12: =IF(COUNT(D12:D13,G12:G13,J12:J13)=0,"",IF(SUM(D12:D13)-SUM(G12:G13)-SUM(J12:J13)=0,"✔","✗"))
E13: = | H13: +
A14: 5 | B14: Depreciação do ano: 40, sendo 30 das máquinas da fábrica e 10 dos móveis do escritório | C14: (-) Depreciação Acumulada | D14: -40 | E14: = | H14: + | I14: Lucros Acumulados | J14: -10 | K14: =IF(COUNT(D14:D15,G14:G15,J14:J15)=0,"",IF(SUM(D14:D15)-SUM(G14:G15)-SUM(J14:J15)=0,"✔","✗"))
C15: Produtos em Elaboração | D15: 30 | E15: = | H15: +
A16: 6 | B16: Produção concluída no ano e transferida para produtos acabados: 470 | C16: Produtos em Elaboração | D16: -470 | E16: = | H16: + | K16: =IF(COUNT(D16:D17,G16:G17,J16:J17)=0,"",IF(SUM(D16:D17)-SUM(G16:G17)-SUM(J16:J17)=0,"✔","✗"))
C17: Produtos Acabados | D17: 470 | E17: = | H17: +
A18: 7 | B18: Vendas do ano: 700, sendo 450 à vista e 250 a prazo; o custo dos produtos vendidos foi 480 | C18: Caixa | D18: 450 | E18: = | H18: + | I18: Lucros Acumulados | J18: 220 | K18: =IF(COUNT(D18:D20,G18:G20,J18:J20)=0,"",IF(SUM(D18:D20)-SUM(G18:G20)-SUM(J18:J20)=0,"✔","✗"))
C19: Contas a Receber | D19: 250 | E19: = | H19: +
C20: Produtos Acabados | D20: -480 | E20: = | H20: +
A21: 8 | B21: Recebimento de 210 de clientes, referente a vendas de anos anteriores | C21: Caixa | D21: 210 | E21: = | H21: + | K21: =IF(COUNT(D21:D22,G21:G22,J21:J22)=0,"",IF(SUM(D21:D22)-SUM(G21:G22)-SUM(J21:J22)=0,"✔","✗"))
C22: Contas a Receber | D22: -210 | E22: = | H22: +
A23: 9 | B23: Pagamento de 230 a fornecedores | C23: Caixa | D23: -230 | E23: = | F23: Fornecedores | G23: -230 | H23: + | K23: =IF(COUNT(D23:D24,G23:G24,J23:J24)=0,"",IF(SUM(D23:D24)-SUM(G23:G24)-SUM(J23:J24)=0,"✔","✗"))
E24: = | H24: +
A25: 10 | B25: Despesas comerciais e administrativas do ano: 90, pagas à vista | C25: Caixa | D25: -90 | E25: = | H25: + | I25: Lucros Acumulados | J25: -90 | K25: =IF(COUNT(D25:D26,G25:G26,J25:J26)=0,"",IF(SUM(D25:D26)-SUM(G25:G26)-SUM(J25:J26)=0,"✔","✗"))
E26: = | H26: +
A27: 11 | B27: Compra à vista de uma nova prensa por 60 | C27: Caixa | D27: -60 | E27: = | H27: + | K27: =IF(COUNT(D27:D28,G27:G28,J27:J28)=0,"",IF(SUM(D27:D28)-SUM(G27:G28)-SUM(J27:J28)=0,"✔","✗"))
C28: Imobilizado | D28: 60 | E28: = | H28: +
A29: 12 | B29: Pagamento de 20 de juros e amortização de 50 do principal da dívida | C29: Caixa | D29: -70 | E29: = | F29: Empréstimos | G29: -50 | H29: + | I29: Lucros Acumulados | J29: -20 | K29: =IF(COUNT(D29:D30,G29:G30,J29:J30)=0,"",IF(SUM(D29:D30)-SUM(G29:G30)-SUM(J29:J30)=0,"✔","✗"))
E30: = | H30: +
A31: 13 | B31: IR e CSLL do ano: 30, pagos integralmente à vista | C31: Caixa | D31: -30 | E31: = | H31: + | I31: Lucros Acumulados | J31: -30 | K31: =IF(COUNT(D31:D32,G31:G32,J31:J32)=0,"",IF(SUM(D31:D32)-SUM(G31:G32)-SUM(J31:J32)=0,"✔","✗"))
E32: = | H32: +
A33: 14 | B33: Dividendos de 25 declarados e pagos em dinheiro | C33: Caixa | D33: -25 | E33: = | H33: + | I33: Lucros Acumulados | J33: -25 | K33: =IF(COUNT(D33:D34,G33:G34,J33:J34)=0,"",IF(SUM(D33:D34)-SUM(G33:G34)-SUM(J33:J34)=0,"✔","✗"))
E34: = | H34: +
