Workbook

Sheet Equação
A1: Transportadora Rota Sul S.A. | Efeito das transações na Equação do Balanço
A2: Uma linha por movimento: escreve a conta e o valor, com sinal. Transação que mexe em três contas do mesmo lado usa as três linhas. A coluna Check acusa se aquela transação fechou.
A4: Nº | B4: Descrição | C4: ATIVO | E4: = | F4: PASSIVO | H4: + | I4: PATRIMÔNIO LÍQUIDO | K4: Check
C5: conta | D5: valor | F5: conta | G5: valor | I5: conta | J5: valor
A6: 1 | B6: Receita de fretes do ano: 920, sendo 620 recebidos à vista e 300 a prazo | E6: = | H6: + | K6: =IF(COUNT(D6:D7,G6:G7,J6:J7)=0,"",IF(SUM(D6:D7)-SUM(G6:G7)-SUM(J6:J7)=0,"✔","✗"))
E7: = | H7: +
A8: 2 | B8: Consumo de 45 de peças da oficina nas manutenções da frota | E8: = | H8: + | K8: =IF(COUNT(D8:D9,G8:G9,J8:J9)=0,"",IF(SUM(D8:D9)-SUM(G8:G9)-SUM(J8:J9)=0,"✔","✗"))
E9: = | H9: +
A10: 3 | B10: Custos de operação pagos à vista (combustível, pedágio e salários de motoristas): 540 | E10: = | H10: + | K10: =IF(COUNT(D10:D11,G10:G11,J10:J11)=0,"",IF(SUM(D10:D11)-SUM(G10:G11)-SUM(J10:J11)=0,"✔","✗"))
E11: = | H11: +
A12: 4 | B12: Compra de peças de reposição por 60, integralmente a prazo | E12: = | H12: + | K12: =IF(COUNT(D12:D13,G12:G13,J12:J13)=0,"",IF(SUM(D12:D13)-SUM(G12:G13)-SUM(J12:J13)=0,"✔","✗"))
E13: = | H13: +
A14: 5 | B14: Venda à vista de um caminhão por 50. Ele custou 180 e tinha 150 de depreciação acumulada | E14: = | H14: + | K14: =IF(COUNT(D14:D16,G14:G16,J14:J16)=0,"",IF(SUM(D14:D16)-SUM(G14:G16)-SUM(J14:J16)=0,"✔","✗"))
E15: = | H15: +
E16: = | H16: +
A17: 6 | B17: Venda à vista de outro caminhão por 25. Ele custou 120 e tinha 80 de depreciação acumulada | E17: = | H17: + | K17: =IF(COUNT(D17:D19,G17:G19,J17:J19)=0,"",IF(SUM(D17:D19)-SUM(G17:G19)-SUM(J17:J19)=0,"✔","✗"))
E18: = | H18: +
E19: = | H19: +
A20: 7 | B20: Compra de dois caminhões novos por 260, sendo 100 à vista e 160 financiados em longo prazo | E20: = | H20: + | K20: =IF(COUNT(D20:D21,G20:G21,J20:J21)=0,"",IF(SUM(D20:D21)-SUM(G20:G21)-SUM(J20:J21)=0,"✔","✗"))
E21: = | H21: +
A22: 8 | B22: Depreciação da frota no ano: 70 | E22: = | H22: + | K22: =IF(COUNT(D22:D23,G22:G23,J22:J23)=0,"",IF(SUM(D22:D23)-SUM(G22:G23)-SUM(J22:J23)=0,"✔","✗"))
E23: = | H23: +
A24: 9 | B24: Baixa de 12 de peças obsoletas, de modelos que saíram da frota | E24: = | H24: + | K24: =IF(COUNT(D24:D25,G24:G25,J24:J25)=0,"",IF(SUM(D24:D25)-SUM(G24:G25)-SUM(J24:J25)=0,"✔","✗"))
E25: = | H25: +
A26: 10 | B26: Constituição de provisão para devedores duvidosos: 18 | E26: = | H26: + | K26: =IF(COUNT(D26:D27,G26:G27,J26:J27)=0,"",IF(SUM(D26:D27)-SUM(G26:G27)-SUM(J26:J27)=0,"✔","✗"))
E27: = | H27: +
A28: 11 | B28: Baixa definitiva de um cliente incobrável de 14, consumindo a provisão já constituída | E28: = | H28: + | K28: =IF(COUNT(D28:D29,G28:G29,J28:J29)=0,"",IF(SUM(D28:D29)-SUM(G28:G29)-SUM(J28:J29)=0,"✔","✗"))
E29: = | H29: +
A30: 12 | B30: Recebimento de 240 de clientes | E30: = | H30: + | K30: =IF(COUNT(D30:D31,G30:G31,J30:J31)=0,"",IF(SUM(D30:D31)-SUM(G30:G31)-SUM(J30:J31)=0,"✔","✗"))
E31: = | H31: +
A32: 13 | B32: Pagamento de 95 a fornecedores | E32: = | H32: + | K32: =IF(COUNT(D32:D33,G32:G33,J32:J33)=0,"",IF(SUM(D32:D33)-SUM(G32:G33)-SUM(J32:J33)=0,"✔","✗"))
E33: = | H33: +
A34: 14 | B34: Despesas administrativas do ano: 110, pagas à vista | E34: = | H34: + | K34: =IF(COUNT(D34:D35,G34:G35,J34:J35)=0,"",IF(SUM(D34:D35)-SUM(G34:G35)-SUM(J34:J35)=0,"✔","✗"))
E35: = | H35: +
A36: 15 | B36: Pagamento de 20 de juros e amortização de 40 do principal da dívida | E36: = | H36: + | K36: =IF(COUNT(D36:D37,G36:G37,J36:J37)=0,"",IF(SUM(D36:D37)-SUM(G36:G37)-SUM(J36:J37)=0,"✔","✗"))
E37: = | H37: +
A38: 16 | B38: IR e CSLL do ano: 33, pagos integralmente à vista | E38: = | H38: + | K38: =IF(COUNT(D38:D39,G38:G39,J38:J39)=0,"",IF(SUM(D38:D39)-SUM(G38:G39)-SUM(J38:J39)=0,"✔","✗"))
E39: = | H39: +
A40: 17 | B40: Dividendos de 20 declarados e pagos em dinheiro | E40: = | H40: + | K40: =IF(COUNT(D40:D41,G40:G41,J40:J41)=0,"",IF(SUM(D40:D41)-SUM(G40:G41)-SUM(J40:J41)=0,"✔","✗"))
E41: = | H41: +

Sheet Plan
B1: Transportadora Rota Sul S.A. | D1: Transações, por Número e Descrição
B2: Ano 4 | valores em R$ mil | D2: Receita de fretes do ano: 920, sendo 620 recebidos à vista e | E2: Consumo de 45 de peças da oficina nas manutenções da frota | F2: Custos de operação pagos à vista (combustível, pedágio e sal | G2: Compra de peças de reposição por 60, integralmente a prazo | H2: Venda à vista de um caminhão por 50. Ele custou 180 e tinha | I2: Venda à vista de outro caminhão por 25. Ele custou 120 e tin | J2: Compra de dois caminhões novos por 260, sendo 100 à vista e | K2: Depreciação da frota no ano: 70 | L2: Baixa de 12 de peças obsoletas, de modelos que saíram da fro | M2: Constituição de provisão para devedores duvidosos: 18 | N2: Baixa definitiva de um cliente incobrável de 14, consumindo | O2: Recebimento de 240 de clientes | P2: Pagamento de 95 a fornecedores | Q2: Despesas administrativas do ano: 110, pagas à vista | R2: Pagamento de 20 de juros e amortização de 40 do principal da | S2: IR e CSLL do ano: 33, pagos integralmente à vista | T2: Dividendos de 20 declarados e pagos em dinheiro
B3: Balanço Patrimonial | C3: Balanço Inicial | D3: 1 | E3: 2 | F3: 3 | G3: 4 | H3: 5 | I3: 6 | J3: 7 | K3: 8 | L3: 9 | M3: 10 | N3: 11 | O3: 12 | P3: 13 | Q3: 14 | R3: 15 | S3: 16 | T3: 17 | U3: Balanço Final
B4: ATIVO
B5: Ativo Circulante
B6: Caixa | C6: 60 | U6: =C6+SUM(D6:T6) | W6: =IF(COUNT(D6:T6)=0,"",IF(ABS(U6-Gabarito!U6)<0.5,"✔","✗"))
B7: Contas a Receber | C7: 200 | U7: =C7+SUM(D7:T7) | W7: =IF(COUNT(D7:T7)=0,"",IF(ABS(U7-Gabarito!U7)<0.5,"✔","✗"))
B8: (-) Provisão p/ Devedores Duvidosos | C8: -10 | U8: =C8+SUM(D8:T8) | W8: =IF(COUNT(D8:T8)=0,"",IF(ABS(U8-Gabarito!U8)<0.5,"✔","✗"))
B9: Estoque de Peças | C9: 70 | U9: =C9+SUM(D9:T9) | W9: =IF(COUNT(D9:T9)=0,"",IF(ABS(U9-Gabarito!U9)<0.5,"✔","✗"))
B10: Ativo Não Circulante
B11: Imobilizado (frota) | C11: 600 | U11: =C11+SUM(D11:T11) | W11: =IF(COUNT(D11:T11)=0,"",IF(ABS(U11-Gabarito!U11)<0.5,"✔","✗"))
B12: (-) Depreciação Acumulada | C12: -240 | U12: =C12+SUM(D12:T12) | W12: =IF(COUNT(D12:T12)=0,"",IF(ABS(U12-Gabarito!U12)<0.5,"✔","✗"))
B13: Total do Ativo | C13: =SUM(C6:C12) | D13: =SUM(D6:D12) | E13: =SUM(E6:E12) | F13: =SUM(F6:F12) | G13: =SUM(G6:G12) | H13: =SUM(H6:H12) | I13: =SUM(I6:I12) | J13: =SUM(J6:J12) | ... U13: =SUM(U6:U12)
B14: PASSIVO E PATRIM. LÍQUIDO
B15: Passivo Circulante:
B16: Fornecedores | C16: 80 | U16: =C16+SUM(D16:T16) | W16: =IF(COUNT(D16:T16)=0,"",IF(ABS(U16-Gabarito!U16)<0.5,"✔","✗"))
B17: Empréstimos | C17: 200 | U17: =C17+SUM(D17:T17) | W17: =IF(COUNT(D17:T17)=0,"",IF(ABS(U17-Gabarito!U17)<0.5,"✔","✗"))
B18: Passivo Não Circulante:
B19: Financiamento a Pagar (LP) | U19: =C19+SUM(D19:T19) | W19: =IF(COUNT(D19:T19)=0,"",IF(ABS(U19-Gabarito!U19)<0.5,"✔","✗"))
B20: Patrimônio Líquido:
B21: Capital Social | C21: 300 | U21: =C21+SUM(D21:T21) | W21: =IF(COUNT(D21:T21)=0,"",IF(ABS(U21-Gabarito!U21)<0.5,"✔","✗"))
B22: Lucros Acumulados | C22: 100 | U22: =C22+SUM(D22:T22) | W22: =IF(COUNT(D22:T22)=0,"",IF(ABS(U22-Gabarito!U22)<0.5,"✔","✗"))
B23: Total Passivo e Patrim. Líquido | C23: =SUM(C15:C22) | D23: =SUM(D15:D22) | E23: =SUM(E15:E22) | F23: =SUM(F15:F22) | G23: =SUM(G15:G22) | H23: =SUM(H15:H22) | I23: =SUM(I15:I22) | J23: =SUM(J15:J22) | ... U23: =SUM(U15:U22)
B25: Diferença, se houver (tem que dar zero) | C25: =C13-C23 | D25: =D13-D23 | E25: =E13-E23 | F25: =F13-F23 | G25: =G13-G23 | H25: =H13-H23 | I25: =I13-I23 | J25: =J13-J23 | ... U25: =U13-U23 | W25: =IF(U25=0,"✔ fecha","✗ não fecha")
B27: Demonstração do Resultado | D27: 1 | E27: 2 | F27: 3 | G27: 4 | H27: 5 | I27: 6 | J27: 7 | K27: 8 | L27: 9 | M27: 10 | N27: 11 | O27: 12 | P27: 13 | Q27: 14 | R27: 15 | S27: 16 | T27: 17 | U27: Ano 4 | W27: Check
B28: Receita de Fretes | U28: =SUM(D28:T28) | W28: =IF(COUNT(D28:T28)=0,"",IF(ABS(U28-Gabarito!U28)<0.5,"✔","✗"))
B29: (-) Custo dos Serviços Prestados | U29: =SUM(D29:T29) | W29: =IF(COUNT(D29:T29)=0,"",IF(ABS(U29-Gabarito!U29)<0.5,"✔","✗"))
B30: (=) Lucro Bruto | D30: =SUM(D28:D29) | E30: =SUM(E28:E29) | F30: =SUM(F28:F29) | G30: =SUM(G28:G29) | H30: =SUM(H28:H29) | I30: =SUM(I28:I29) | J30: =SUM(J28:J29) | K30: =SUM(K28:K29) | ... U30: =SUM(U28:U29)
B31: (-) Despesas Administrativas | U31: =SUM(D31:T31) | W31: =IF(COUNT(D31:T31)=0,"",IF(ABS(U31-Gabarito!U31)<0.5,"✔","✗"))
B32: (-) Depreciação | U32: =SUM(D32:T32) | W32: =IF(COUNT(D32:T32)=0,"",IF(ABS(U32-Gabarito!U32)<0.5,"✔","✗"))
B33: (-) Perda com Estoque Obsoleto | U33: =SUM(D33:T33) | W33: =IF(COUNT(D33:T33)=0,"",IF(ABS(U33-Gabarito!U33)<0.5,"✔","✗"))
B34: (-) Despesa com Devedores Duvidosos | U34: =SUM(D34:T34) | W34: =IF(COUNT(D34:T34)=0,"",IF(ABS(U34-Gabarito!U34)<0.5,"✔","✗"))
B35: (+/-) Resultado na Venda de Imobilizado | U35: =SUM(D35:T35) | W35: =IF(COUNT(D35:T35)=0,"",IF(ABS(U35-Gabarito!U35)<0.5,"✔","✗"))
B36: (=) EBIT | D36: =SUM(D30:D35) | E36: =SUM(E30:E35) | F36: =SUM(F30:F35) | G36: =SUM(G30:G35) | H36: =SUM(H30:H35) | I36: =SUM(I30:I35) | J36: =SUM(J30:J35) | K36: =SUM(K30:K35) | ... U36: =SUM(U30:U35)
B37: (+/-) Resultado Financeiro | U37: =SUM(D37:T37) | W37: =IF(COUNT(D37:T37)=0,"",IF(ABS(U37-Gabarito!U37)<0.5,"✔","✗"))
B38: (=) LAIR | D38: =SUM(D36:D37) | E38: =SUM(E36:E37) | F38: =SUM(F36:F37) | G38: =SUM(G36:G37) | H38: =SUM(H36:H37) | I38: =SUM(I36:I37) | J38: =SUM(J36:J37) | K38: =SUM(K36:K37) | ... U38: =SUM(U36:U37)
B39: (-) IR e CSLL | U39: =SUM(D39:T39) | W39: =IF(COUNT(D39:T39)=0,"",IF(ABS(U39-Gabarito!U39)<0.5,"✔","✗"))
B40: (=) Lucro Líquido | D40: =SUM(D38:D39) | E40: =SUM(E38:E39) | F40: =SUM(F38:F39) | G40: =SUM(G38:G39) | H40: =SUM(H38:H39) | I40: =SUM(I38:I39) | J40: =SUM(J38:J39) | K40: =SUM(K38:K39) | ... U40: =SUM(U38:U39)
B42: Demonstração dos Fluxos de Caixa | D42: 1 | E42: 2 | F42: 3 | G42: 4 | H42: 5 | I42: 6 | J42: 7 | K42: 8 | L42: 9 | M42: 10 | N42: 11 | O42: 12 | P42: 13 | Q42: 14 | R42: 15 | S42: 16 | T42: 17 | U42: Ano 4
B43: OPERAÇÕES | D43: =SUM(D44:D49) | E43: =SUM(E44:E49) | F43: =SUM(F44:F49) | G43: =SUM(G44:G49) | H43: =SUM(H44:H49) | I43: =SUM(I44:I49) | J43: =SUM(J44:J49) | K43: =SUM(K44:K49) | ... U43: =SUM(U44:U49)
...

Sheet Gabarito
B1: Transportadora Rota Sul S.A. | D1: Transações, por Número e Descrição
B2: Ano 4 | valores em R$ mil | D2: Receita de fretes do ano: 920, sendo 620 recebidos à vista e | E2: Consumo de 45 de peças da oficina nas manutenções da frota | F2: Custos de operação pagos à vista (combustível, pedágio e sal | G2: Compra de peças de reposição por 60, integralmente a prazo | H2: Venda à vista de um caminhão por 50. Ele custou 180 e tinha | I2: Venda à vista de outro caminhão por 25. Ele custou 120 e tin | J2: Compra de dois caminhões novos por 260, sendo 100 à vista e | K2: Depreciação da frota no ano: 70 | L2: Baixa de 12 de peças obsoletas, de modelos que saíram da fro | M2: Constituição de provisão para devedores duvidosos: 18 | N2: Baixa definitiva de um cliente incobrável de 14, consumindo | O2: Recebimento de 240 de clientes | P2: Pagamento de 95 a fornecedores | Q2: Despesas administrativas do ano: 110, pagas à vista | R2: Pagamento de 20 de juros e amortização de 40 do principal da | S2: IR e CSLL do ano: 33, pagos integralmente à vista | T2: Dividendos de 20 declarados e pagos em dinheiro
B3: Balanço Patrimonial | C3: Balanço Inicial | D3: 1 | E3: 2 | F3: 3 | G3: 4 | H3: 5 | I3: 6 | J3: 7 | K3: 8 | L3: 9 | M3: 10 | N3: 11 | O3: 12 | P3: 13 | Q3: 14 | R3: 15 | S3: 16 | T3: 17 | U3: Balanço Final
B4: ATIVO
B5: Ativo Circulante
B6: Caixa | C6: 60 | D6: 620 | F6: -540 | H6: 50 | I6: 25 | J6: -100 | O6: 240 | P6: -95 | Q6: -110 | R6: -60 | S6: -33 | T6: -20 | U6: =C6+SUM(D6:T6)
B7: Contas a Receber | C7: 200 | D7: 300 | N7: -14 | O7: -240 | U7: =C7+SUM(D7:T7)
B8: (-) Provisão p/ Devedores Duvidosos | C8: -10 | M8: -18 | N8: 14 | U8: =C8+SUM(D8:T8)
B9: Estoque de Peças | C9: 70 | E9: -45 | G9: 60 | L9: -12 | U9: =C9+SUM(D9:T9)
B10: Ativo Não Circulante
B11: Imobilizado (frota) | C11: 600 | H11: -180 | I11: -120 | J11: 260 | U11: =C11+SUM(D11:T11)
B12: (-) Depreciação Acumulada | C12: -240 | H12: 150 | I12: 80 | K12: -70 | U12: =C12+SUM(D12:T12)
B13: Total do Ativo | C13: =SUM(C6:C12) | D13: =SUM(D6:D12) | E13: =SUM(E6:E12) | F13: =SUM(F6:F12) | G13: =SUM(G6:G12) | H13: =SUM(H6:H12) | I13: =SUM(I6:I12) | J13: =SUM(J6:J12) | ... U13: =SUM(U6:U12)
B14: PASSIVO E PATRIM. LÍQUIDO
B15: Passivo Circulante:
B16: Fornecedores | C16: 80 | G16: 60 | P16: -95 | U16: =C16+SUM(D16:T16)
B17: Empréstimos | C17: 200 | R17: -40 | U17: =C17+SUM(D17:T17)
B18: Passivo Não Circulante:
B19: Financiamento a Pagar (LP) | J19: 160 | U19: =C19+SUM(D19:T19)
B20: Patrimônio Líquido:
B21: Capital Social | C21: 300 | U21: =C21+SUM(D21:T21)
B22: Lucros Acumulados | C22: 100 | D22: 920 | E22: -45 | F22: -540 | H22: 20 | I22: -15 | K22: -70 | L22: -12 | M22: -18 | Q22: -110 | R22: -20 | S22: -33 | T22: -20 | U22: =C22+SUM(D22:T22)
B23: Total Passivo e Patrim. Líquido | C23: =SUM(C15:C22) | D23: =SUM(D15:D22) | E23: =SUM(E15:E22) | F23: =SUM(F15:F22) | G23: =SUM(G15:G22) | H23: =SUM(H15:H22) | I23: =SUM(I15:I22) | J23: =SUM(J15:J22) | ... U23: =SUM(U15:U22)
B25: Diferença, se houver (tem que dar zero) | C25: =C13-C23 | D25: =D13-D23 | E25: =E13-E23 | F25: =F13-F23 | G25: =G13-G23 | H25: =H13-H23 | I25: =I13-I23 | J25: =J13-J23 | ... U25: =U13-U23
B27: Demonstração do Resultado | D27: 1 | E27: 2 | F27: 3 | G27: 4 | H27: 5 | I27: 6 | J27: 7 | K27: 8 | L27: 9 | M27: 10 | N27: 11 | O27: 12 | P27: 13 | Q27: 14 | R27: 15 | S27: 16 | T27: 17 | U27: Ano 4 | W27: Check
B28: Receita de Fretes | D28: 920 | U28: =SUM(D28:T28)
B29: (-) Custo dos Serviços Prestados | E29: -45 | F29: -540 | U29: =SUM(D29:T29)
B30: (=) Lucro Bruto | D30: =SUM(D28:D29) | E30: =SUM(E28:E29) | F30: =SUM(F28:F29) | G30: =SUM(G28:G29) | H30: =SUM(H28:H29) | I30: =SUM(I28:I29) | J30: =SUM(J28:J29) | K30: =SUM(K28:K29) | ... U30: =SUM(U28:U29)
B31: (-) Despesas Administrativas | Q31: -110 | U31: =SUM(D31:T31)
B32: (-) Depreciação | K32: -70 | U32: =SUM(D32:T32)
B33: (-) Perda com Estoque Obsoleto | L33: -12 | U33: =SUM(D33:T33)
B34: (-) Despesa com Devedores Duvidosos | M34: -18 | U34: =SUM(D34:T34)
B35: (+/-) Resultado na Venda de Imobilizado | H35: 20 | I35: -15 | U35: =SUM(D35:T35)
B36: (=) EBIT | D36: =SUM(D30:D35) | E36: =SUM(E30:E35) | F36: =SUM(F30:F35) | G36: =SUM(G30:G35) | H36: =SUM(H30:H35) | I36: =SUM(I30:I35) | J36: =SUM(J30:J35) | K36: =SUM(K30:K35) | ... U36: =SUM(U30:U35)
B37: (+/-) Resultado Financeiro | R37: -20 | U37: =SUM(D37:T37)
B38: (=) LAIR | D38: =SUM(D36:D37) | E38: =SUM(E36:E37) | F38: =SUM(F36:F37) | G38: =SUM(G36:G37) | H38: =SUM(H36:H37) | I38: =SUM(I36:I37) | J38: =SUM(J36:J37) | K38: =SUM(K36:K37) | ... U38: =SUM(U36:U37)
B39: (-) IR e CSLL | S39: -33 | U39: =SUM(D39:T39)
B40: (=) Lucro Líquido | D40: =SUM(D38:D39) | E40: =SUM(E38:E39) | F40: =SUM(F38:F39) | G40: =SUM(G38:G39) | H40: =SUM(H38:H39) | I40: =SUM(I38:I39) | J40: =SUM(J38:J39) | K40: =SUM(K38:K39) | ... U40: =SUM(U38:U39)
B42: Demonstração dos Fluxos de Caixa | D42: 1 | E42: 2 | F42: 3 | G42: 4 | H42: 5 | I42: 6 | J42: 7 | K42: 8 | L42: 9 | M42: 10 | N42: 11 | O42: 12 | P42: 13 | Q42: 14 | R42: 15 | S42: 16 | T42: 17 | U42: Ano 4
B43: OPERAÇÕES | D43: =SUM(D44:D49) | E43: =SUM(E44:E49) | F43: =SUM(F44:F49) | G43: =SUM(G44:G49) | H43: =SUM(H44:H49) | I43: =SUM(I44:I49) | J43: =SUM(J44:J49) | K43: =SUM(K44:K49) | ... U43: =SUM(U44:U49)
...

Sheet Gabarito Equação
A1: Transportadora Rota Sul S.A. | Efeito das transações na Equação do Balanço
A2: Uma linha por movimento: escreve a conta e o valor, com sinal. Transação que mexe em três contas do mesmo lado usa as três linhas. A coluna Check acusa se aquela transação fechou.
A4: Nº | B4: Descrição | C4: ATIVO | E4: = | F4: PASSIVO | H4: + | I4: PATRIMÔNIO LÍQUIDO | K4: Check
C5: conta | D5: valor | F5: conta | G5: valor | I5: conta | J5: valor
A6: 1 | B6: Receita de fretes do ano: 920, sendo 620 recebidos à vista e 300 a prazo | C6: Caixa | D6: 620 | E6: = | H6: + | I6: Lucros Acumulados | J6: 920 | K6: =IF(COUNT(D6:D7,G6:G7,J6:J7)=0,"",IF(SUM(D6:D7)-SUM(G6:G7)-SUM(J6:J7)=0,"✔","✗"))
C7: Contas a Receber | D7: 300 | E7: = | H7: +
A8: 2 | B8: Consumo de 45 de peças da oficina nas manutenções da frota | C8: Estoque de Peças | D8: -45 | E8: = | H8: + | I8: Lucros Acumulados | J8: -45 | K8: =IF(COUNT(D8:D9,G8:G9,J8:J9)=0,"",IF(SUM(D8:D9)-SUM(G8:G9)-SUM(J8:J9)=0,"✔","✗"))
E9: = | H9: +
A10: 3 | B10: Custos de operação pagos à vista (combustível, pedágio e salários de motoristas): 540 | C10: Caixa | D10: -540 | E10: = | H10: + | I10: Lucros Acumulados | J10: -540 | K10: =IF(COUNT(D10:D11,G10:G11,J10:J11)=0,"",IF(SUM(D10:D11)-SUM(G10:G11)-SUM(J10:J11)=0,"✔","✗"))
E11: = | H11: +
A12: 4 | B12: Compra de peças de reposição por 60, integralmente a prazo | C12: Estoque de Peças | D12: 60 | E12: = | F12: Fornecedores | G12: 60 | H12: + | K12: =IF(COUNT(D12:D13,G12:G13,J12:J13)=0,"",IF(SUM(D12:D13)-SUM(G12:G13)-SUM(J12:J13)=0,"✔","✗"))
E13: = | H13: +
A14: 5 | B14: Venda à vista de um caminhão por 50. Ele custou 180 e tinha 150 de depreciação acumulada | C14: Caixa | D14: 50 | E14: = | H14: + | I14: Lucros Acumulados | J14: 20 | K14: =IF(COUNT(D14:D16,G14:G16,J14:J16)=0,"",IF(SUM(D14:D16)-SUM(G14:G16)-SUM(J14:J16)=0,"✔","✗"))
C15: Imobilizado (frota) | D15: -180 | E15: = | H15: +
C16: (-) Depreciação Acumulada | D16: 150 | E16: = | H16: +
A17: 6 | B17: Venda à vista de outro caminhão por 25. Ele custou 120 e tinha 80 de depreciação acumulada | C17: Caixa | D17: 25 | E17: = | H17: + | I17: Lucros Acumulados | J17: -15 | K17: =IF(COUNT(D17:D19,G17:G19,J17:J19)=0,"",IF(SUM(D17:D19)-SUM(G17:G19)-SUM(J17:J19)=0,"✔","✗"))
C18: Imobilizado (frota) | D18: -120 | E18: = | H18: +
C19: (-) Depreciação Acumulada | D19: 80 | E19: = | H19: +
A20: 7 | B20: Compra de dois caminhões novos por 260, sendo 100 à vista e 160 financiados em longo prazo | C20: Caixa | D20: -100 | E20: = | F20: Financiamento a Pagar (LP) | G20: 160 | H20: + | K20: =IF(COUNT(D20:D21,G20:G21,J20:J21)=0,"",IF(SUM(D20:D21)-SUM(G20:G21)-SUM(J20:J21)=0,"✔","✗"))
C21: Imobilizado (frota) | D21: 260 | E21: = | H21: +
A22: 8 | B22: Depreciação da frota no ano: 70 | C22: (-) Depreciação Acumulada | D22: -70 | E22: = | H22: + | I22: Lucros Acumulados | J22: -70 | K22: =IF(COUNT(D22:D23,G22:G23,J22:J23)=0,"",IF(SUM(D22:D23)-SUM(G22:G23)-SUM(J22:J23)=0,"✔","✗"))
E23: = | H23: +
A24: 9 | B24: Baixa de 12 de peças obsoletas, de modelos que saíram da frota | C24: Estoque de Peças | D24: -12 | E24: = | H24: + | I24: Lucros Acumulados | J24: -12 | K24: =IF(COUNT(D24:D25,G24:G25,J24:J25)=0,"",IF(SUM(D24:D25)-SUM(G24:G25)-SUM(J24:J25)=0,"✔","✗"))
E25: = | H25: +
A26: 10 | B26: Constituição de provisão para devedores duvidosos: 18 | C26: (-) Provisão p/ Devedores Duvidosos | D26: -18 | E26: = | H26: + | I26: Lucros Acumulados | J26: -18 | K26: =IF(COUNT(D26:D27,G26:G27,J26:J27)=0,"",IF(SUM(D26:D27)-SUM(G26:G27)-SUM(J26:J27)=0,"✔","✗"))
E27: = | H27: +
A28: 11 | B28: Baixa definitiva de um cliente incobrável de 14, consumindo a provisão já constituída | C28: Contas a Receber | D28: -14 | E28: = | H28: + | K28: =IF(COUNT(D28:D29,G28:G29,J28:J29)=0,"",IF(SUM(D28:D29)-SUM(G28:G29)-SUM(J28:J29)=0,"✔","✗"))
C29: (-) Provisão p/ Devedores Duvidosos | D29: 14 | E29: = | H29: +
A30: 12 | B30: Recebimento de 240 de clientes | C30: Caixa | D30: 240 | E30: = | H30: + | K30: =IF(COUNT(D30:D31,G30:G31,J30:J31)=0,"",IF(SUM(D30:D31)-SUM(G30:G31)-SUM(J30:J31)=0,"✔","✗"))
C31: Contas a Receber | D31: -240 | E31: = | H31: +
A32: 13 | B32: Pagamento de 95 a fornecedores | C32: Caixa | D32: -95 | E32: = | F32: Fornecedores | G32: -95 | H32: + | K32: =IF(COUNT(D32:D33,G32:G33,J32:J33)=0,"",IF(SUM(D32:D33)-SUM(G32:G33)-SUM(J32:J33)=0,"✔","✗"))
E33: = | H33: +
A34: 14 | B34: Despesas administrativas do ano: 110, pagas à vista | C34: Caixa | D34: -110 | E34: = | H34: + | I34: Lucros Acumulados | J34: -110 | K34: =IF(COUNT(D34:D35,G34:G35,J34:J35)=0,"",IF(SUM(D34:D35)-SUM(G34:G35)-SUM(J34:J35)=0,"✔","✗"))
E35: = | H35: +
A36: 15 | B36: Pagamento de 20 de juros e amortização de 40 do principal da dívida | C36: Caixa | D36: -60 | E36: = | F36: Empréstimos | G36: -40 | H36: + | I36: Lucros Acumulados | J36: -20 | K36: =IF(COUNT(D36:D37,G36:G37,J36:J37)=0,"",IF(SUM(D36:D37)-SUM(G36:G37)-SUM(J36:J37)=0,"✔","✗"))
E37: = | H37: +
A38: 16 | B38: IR e CSLL do ano: 33, pagos integralmente à vista | C38: Caixa | D38: -33 | E38: = | H38: + | I38: Lucros Acumulados | J38: -33 | K38: =IF(COUNT(D38:D39,G38:G39,J38:J39)=0,"",IF(SUM(D38:D39)-SUM(G38:G39)-SUM(J38:J39)=0,"✔","✗"))
E39: = | H39: +
A40: 17 | B40: Dividendos de 20 declarados e pagos em dinheiro | C40: Caixa | D40: -20 | E40: = | H40: + | I40: Lucros Acumulados | J40: -20 | K40: =IF(COUNT(D40:D41,G40:G41,J40:J41)=0,"",IF(SUM(D40:D41)-SUM(G40:G41)-SUM(J40:J41)=0,"✔","✗"))
E41: = | H41: +
