Workbook

Sheet Dados
B1: Editora Farol S.A.
B2: Dados do caso, em R$ mil. Não altera nada nesta aba.
B4: Balanço Patrimonial | C4: Ano 1 | D4: Ano 2 | E4: Variação
B5: ATIVO
B6: Ativo Circulante
B7: Caixa e Equivalentes | C7: 90 | D7: 145 | E7: =D7-C7
B8: Contas a Receber | C8: 320 | D8: 395 | E8: =D8-C8
B9: Estoques | C9: 210 | D9: 180 | E9: =D9-C9
B10: Despesas Antecipadas | C10: 15 | D10: 25 | E10: =D10-C10
B11: Ativo Não Circulante
B12: Imobilizado | C12: 800 | D12: 960 | E12: =D12-C12
B13: (-) Depreciação Acumulada | C13: -280 | D13: -340 | E13: =D13-C13
B14: Total do Ativo | C14: 1155 | D14: 1365 | E14: =D14-C14
B15: PASSIVO E PATRIM. LÍQUIDO
B16: Passivo Circulante
B17: Fornecedores | C17: 240 | D17: 285 | E17: =D17-C17
B18: Salários e Encargos a Pagar | C18: 45 | D18: 38 | E18: =D18-C18
B19: IR a Pagar | C19: 30 | D19: 42 | E19: =D19-C19
B20: Empréstimos de Curto Prazo | C20: 100 | D20: 130 | E20: =D20-C20
B21: Passivo Não Circulante
B22: Empréstimos de Longo Prazo | C22: 260 | D22: 300 | E22: =D22-C22
B23: Patrimônio Líquido
B24: Capital Social | C24: 300 | D24: 350 | E24: =D24-C24
B25: Lucros Acumulados | C25: 180 | D25: 220 | E25: =D25-C25
B26: Total Passivo e Patrim. Líquido | C26: 1155 | D26: 1365 | E26: =D26-C26
B28: Demonstração do Resultado do Ano 2 | D28: Ano 2
B29: Receita Líquida | D29: 1680
B30: (-) Custo dos Produtos Vendidos | D30: -1010
B31: (=) Lucro Bruto | D31: 670
B32: (-) Despesas Comerciais e Administrativas | D32: -400
B33: (-) Depreciação | D33: -95
B34: (-) Perda na Venda de Imobilizado | D34: -12
B35: (=) EBIT | D35: 163
B36: (+/-) Resultado Financeiro | D36: -45
B37: (=) LAIR | D37: 118
B38: (-) IR e CSLL | D38: -38
B39: (=) Lucro Líquido | D39: 80
B41: Informações adicionais
B42: 1. A empresa vendeu um equipamento à vista por 28. Ele custava 75 e tinha 35 de depreciação acumulada.
B43: 2. A depreciação registrada no ano foi de 95. Não houve outra baixa de imobilizado além da venda acima.
...

Sheet DFC
B1: Editora Farol S.A. | Demonstração dos Fluxos de Caixa do Ano 2
B2: Deriva tudo dos dois balanços e da DRE da aba Dados. Saídas de caixa entram negativas.
B4: PARTE A: FCO pelo método indireto | C4: Seu valor | D4: Check
B5: Lucro Líquido | D5: =IF(C5="","",IF(ABS(C5-Gabarito!C5)<0.5,"✔","✗"))
B6: (+) Depreciação | D6: =IF(C6="","",IF(ABS(C6-Gabarito!C6)<0.5,"✔","✗"))
B7: (+) Perda na venda de imobilizado | D7: =IF(C7="","",IF(ABS(C7-Gabarito!C7)<0.5,"✔","✗"))
B8: (+/-) Variação de Contas a Receber | D8: =IF(C8="","",IF(ABS(C8-Gabarito!C8)<0.5,"✔","✗"))
B9: (+/-) Variação de Estoques | D9: =IF(C9="","",IF(ABS(C9-Gabarito!C9)<0.5,"✔","✗"))
B10: (+/-) Variação de Despesas Antecipadas | D10: =IF(C10="","",IF(ABS(C10-Gabarito!C10)<0.5,"✔","✗"))
B11: (+/-) Variação de Fornecedores | D11: =IF(C11="","",IF(ABS(C11-Gabarito!C11)<0.5,"✔","✗"))
B12: (+/-) Variação de Salários a Pagar | D12: =IF(C12="","",IF(ABS(C12-Gabarito!C12)<0.5,"✔","✗"))
B13: (+/-) Variação de IR a Pagar | D13: =IF(C13="","",IF(ABS(C13-Gabarito!C13)<0.5,"✔","✗"))
B14: (=) FCO | C14: =SUM(C5:C13)
B16: FLUXO DE CAIXA DE INVESTIMENTO | C16: Seu valor | D16: Check
B17: Venda de Imobilizado | D17: =IF(C17="","",IF(ABS(C17-Gabarito!C17)<0.5,"✔","✗"))
B18: (-) Aquisição de Imobilizado | D18: =IF(C18="","",IF(ABS(C18-Gabarito!C18)<0.5,"✔","✗"))
B19: (=) FCI | C19: =SUM(C17:C18)
B21: FLUXO DE CAIXA DE FINANCIAMENTO | C21: Seu valor | D21: Check
B22: Captação de Empréstimos | D22: =IF(C22="","",IF(ABS(C22-Gabarito!C22)<0.5,"✔","✗"))
B23: (-) Amortização de Empréstimos | D23: =IF(C23="","",IF(ABS(C23-Gabarito!C23)<0.5,"✔","✗"))
B24: Aumento de Capital | D24: =IF(C24="","",IF(ABS(C24-Gabarito!C24)<0.5,"✔","✗"))
B25: (-) Dividendos Pagos | D25: =IF(C25="","",IF(ABS(C25-Gabarito!C25)<0.5,"✔","✗"))
B26: (=) FCF | C26: =SUM(C22:C25)
B28: VARIAÇÃO DO CAIXA NO ANO | C28: =C14+C19+C26
B29: Caixa do balanço do Ano 1 | C29: =Dados!C7
B30: Caixa do balanço do Ano 2 (calculado) | C30: =C29+C28
B31: Confere com o balanço? (tem que dar zero) | C31: =C30-Dados!D7 | D31: =IF(C31=0,"✔ fecha","✗")
B33: PARTE B: o mesmo FCO pelo método direto | C33: Seu valor | D33: Check
B34: Recebimentos de Clientes | D34: =IF(C34="","",IF(ABS(C34-Gabarito!C34)<0.5,"✔","✗"))
B35: (-) Pagamentos a Fornecedores | D35: =IF(C35="","",IF(ABS(C35-Gabarito!C35)<0.5,"✔","✗"))
B36: (-) Pagamentos de Salários e Despesas | D36: =IF(C36="","",IF(ABS(C36-Gabarito!C36)<0.5,"✔","✗"))
B37: (-) Juros Pagos | D37: =IF(C37="","",IF(ABS(C37-Gabarito!C37)<0.5,"✔","✗"))
B38: (-) IR Pago | D38: =IF(C38="","",IF(ABS(C38-Gabarito!C38)<0.5,"✔","✗"))
B39: (=) FCO | C39: =SUM(C34:C38)
B41: Direto menos indireto (tem que dar zero) | C41: =C39-C14 | D41: =IF(C41=0,"✔ bate","✗")

Sheet Gabarito
B1: Editora Farol S.A. | Demonstração dos Fluxos de Caixa do Ano 2
B2: Deriva tudo dos dois balanços e da DRE da aba Dados. Saídas de caixa entram negativas.
B4: PARTE A: FCO pelo método indireto | C4: Seu valor | D4: Check
B5: Lucro Líquido | C5: 80
B6: (+) Depreciação | C6: 95
B7: (+) Perda na venda de imobilizado | C7: 12
B8: (+/-) Variação de Contas a Receber | C8: -75
B9: (+/-) Variação de Estoques | C9: 30
B10: (+/-) Variação de Despesas Antecipadas | C10: -10
B11: (+/-) Variação de Fornecedores | C11: 45
B12: (+/-) Variação de Salários a Pagar | C12: -7
B13: (+/-) Variação de IR a Pagar | C13: 12
B14: (=) FCO | C14: =SUM(C5:C13)
B16: FLUXO DE CAIXA DE INVESTIMENTO | C16: Seu valor | D16: Check
B17: Venda de Imobilizado | C17: 28
B18: (-) Aquisição de Imobilizado | C18: -235
B19: (=) FCI | C19: =SUM(C17:C18)
B21: FLUXO DE CAIXA DE FINANCIAMENTO | C21: Seu valor | D21: Check
B22: Captação de Empréstimos | C22: 180
B23: (-) Amortização de Empréstimos | C23: -110
B24: Aumento de Capital | C24: 50
B25: (-) Dividendos Pagos | C25: -40
B26: (=) FCF | C26: =SUM(C22:C25)
B28: VARIAÇÃO DO CAIXA NO ANO | C28: =C14+C19+C26
B29: Caixa do balanço do Ano 1 | C29: =Dados!C7
B30: Caixa do balanço do Ano 2 (calculado) | C30: =C29+C28
B31: Confere com o balanço? (tem que dar zero) | C31: =C30-Dados!D7
B33: PARTE B: o mesmo FCO pelo método direto | C33: Seu valor | D33: Check
B34: Recebimentos de Clientes | C34: 1605
B35: (-) Pagamentos a Fornecedores | C35: -935
B36: (-) Pagamentos de Salários e Despesas | C36: -417
B37: (-) Juros Pagos | C37: -45
B38: (-) IR Pago | C38: -26
B39: (=) FCO | C39: =SUM(C34:C38)
B41: Direto menos indireto (tem que dar zero) | C41: =C39-C14
