Workbook

Sheet Equação
A1: Cafeteria Grão de Ouro | Efeito das transações na Equação do Balanço
A2: Uma linha por movimento: escreve a conta e o valor, com sinal. Transação que mexe em três contas do mesmo lado usa as três linhas. A coluna Check acusa se aquela transação fechou.
A4: Nº | B4: Descrição | C4: ATIVO | E4: = | F4: PASSIVO | H4: + | I4: PATRIMÔNIO LÍQUIDO | K4: Check
C5: conta | D5: valor | F5: conta | G5: valor | I5: conta | J5: valor
A6: 1 | B6: Integralização de capital de R$ 80.000 em dinheiro | E6: = | H6: + | K6: =IF(COUNT(D6:D7,G6:G7,J6:J7)=0,"",IF(SUM(D6:D7)-SUM(G6:G7)-SUM(J6:J7)=0,"✔","✗"))
E7: = | H7: +
A8: 2 | B8: Compra à vista de máquina de espresso e mobiliário por R$ 30.000 | E8: = | H8: + | K8: =IF(COUNT(D8:D9,G8:G9,J8:J9)=0,"",IF(SUM(D8:D9)-SUM(G8:G9)-SUM(J8:J9)=0,"✔","✗"))
E9: = | H9: +
A10: 3 | B10: Compra de café e insumos por R$ 24.000, metade à vista e metade a prazo | E10: = | H10: + | K10: =IF(COUNT(D10:D11,G10:G11,J10:J11)=0,"",IF(SUM(D10:D11)-SUM(G10:G11)-SUM(J10:J11)=0,"✔","✗"))
E11: = | H11: +
A12: 4 | B12: Venda de metade do estoque por R$ 27.000 à vista (custo de R$ 12.000) | E12: = | H12: + | K12: =IF(COUNT(D12:D13,G12:G13,J12:J13)=0,"",IF(SUM(D12:D13)-SUM(G12:G13)-SUM(J12:J13)=0,"✔","✗"))
E13: = | H13: +
A14: 5 | B14: Pagamento de salários e aluguel do mês, R$ 6.000 à vista | E14: = | H14: + | K14: =IF(COUNT(D14:D15,G14:G15,J14:J15)=0,"",IF(SUM(D14:D15)-SUM(G14:G15)-SUM(J14:J15)=0,"✔","✗"))
E15: = | H15: +
A16: 6 | B16: Pagamento de metade do que devia aos fornecedores | E16: = | H16: + | K16: =IF(COUNT(D16:D17,G16:G17,J16:J17)=0,"",IF(SUM(D16:D17)-SUM(G16:G17)-SUM(J16:J17)=0,"✔","✗"))
E17: = | H17: +

Sheet Plan
B1: Cafeteria Grão de Ouro | D1: Transações, por Número e Descrição
B2: Mês 1 | valores em R$ | D2: Integralização de capital de R$ 80.000 em dinheiro | E2: Compra à vista de máquina de espresso e mobiliário por R$ 30 | F2: Compra de café e insumos por R$ 24.000, metade à vista e met | G2: Venda de metade do estoque por R$ 27.000 à vista (custo de R | H2: Pagamento de salários e aluguel do mês, R$ 6.000 à vista | I2: Pagamento de metade do que devia aos fornecedores
B3: Balanço Patrimonial | C3: Balanço Inicial | D3: 1 | E3: 2 | F3: 3 | G3: 4 | H3: 5 | I3: 6 | J3: Balanço Final
B4: ATIVO
B5: Ativo Circulante
B6: Caixa | J6: =C6+SUM(D6:I6) | L6: =IF(COUNT(D6:I6)=0,"",IF(ABS(J6-Gabarito!J6)<0.5,"✔","✗"))
B7: Estoque | J7: =C7+SUM(D7:I7) | L7: =IF(COUNT(D7:I7)=0,"",IF(ABS(J7-Gabarito!J7)<0.5,"✔","✗"))
B8: Ativo Não Circulante
B9: Imobilizado | J9: =C9+SUM(D9:I9) | L9: =IF(COUNT(D9:I9)=0,"",IF(ABS(J9-Gabarito!J9)<0.5,"✔","✗"))
B10: Total do Ativo | C10: =SUM(C6:C9) | D10: =SUM(D6:D9) | E10: =SUM(E6:E9) | F10: =SUM(F6:F9) | G10: =SUM(G6:G9) | H10: =SUM(H6:H9) | I10: =SUM(I6:I9) | J10: =SUM(J6:J9)
B11: PASSIVO E PATRIM. LÍQUIDO
B12: Passivo Circulante:
B13: Contas a Pagar | J13: =C13+SUM(D13:I13) | L13: =IF(COUNT(D13:I13)=0,"",IF(ABS(J13-Gabarito!J13)<0.5,"✔","✗"))
B14: Patrimônio Líquido:
B15: Capital Social | J15: =C15+SUM(D15:I15) | L15: =IF(COUNT(D15:I15)=0,"",IF(ABS(J15-Gabarito!J15)<0.5,"✔","✗"))
B16: Lucros Acumulados | J16: =C16+SUM(D16:I16) | L16: =IF(COUNT(D16:I16)=0,"",IF(ABS(J16-Gabarito!J16)<0.5,"✔","✗"))
B17: Total Passivo e Patrim. Líquido | C17: =SUM(C12:C16) | D17: =SUM(D12:D16) | E17: =SUM(E12:E16) | F17: =SUM(F12:F16) | G17: =SUM(G12:G16) | H17: =SUM(H12:H16) | I17: =SUM(I12:I16) | J17: =SUM(J12:J16)
B19: Diferença, se houver (tem que dar zero) | C19: =C10-C17 | D19: =D10-D17 | E19: =E10-E17 | F19: =F10-F17 | G19: =G10-G17 | H19: =H10-H17 | I19: =I10-I17 | J19: =J10-J17 | L19: =IF(J19=0,"✔ fecha","✗ não fecha")
B21: Demonstração do Resultado | D21: 1 | E21: 2 | F21: 3 | G21: 4 | H21: 5 | I21: 6 | J21: Mês 1 | L21: Check
B22: Receita de Vendas | J22: =SUM(D22:I22) | L22: =IF(COUNT(D22:I22)=0,"",IF(ABS(J22-Gabarito!J22)<0.5,"✔","✗"))
B23: (-) Custo das Mercadorias Vendidas | J23: =SUM(D23:I23) | L23: =IF(COUNT(D23:I23)=0,"",IF(ABS(J23-Gabarito!J23)<0.5,"✔","✗"))
B24: (=) Lucro Bruto | D24: =SUM(D22:D23) | E24: =SUM(E22:E23) | F24: =SUM(F22:F23) | G24: =SUM(G22:G23) | H24: =SUM(H22:H23) | I24: =SUM(I22:I23) | J24: =SUM(J22:J23)
B25: (-) Despesas Operacionais | J25: =SUM(D25:I25) | L25: =IF(COUNT(D25:I25)=0,"",IF(ABS(J25-Gabarito!J25)<0.5,"✔","✗"))
B26: (=) EBIT e Lucro Líquido | D26: =SUM(D24:D25) | E26: =SUM(E24:E25) | F26: =SUM(F24:F25) | G26: =SUM(G24:G25) | H26: =SUM(H24:H25) | I26: =SUM(I24:I25) | J26: =SUM(J24:J25)
B28: Demonstração dos Fluxos de Caixa | D28: 1 | E28: 2 | F28: 3 | G28: 4 | H28: 5 | I28: 6 | J28: Mês 1
B29: OPERAÇÕES | D29: =SUM(D30:D32) | E29: =SUM(E30:E32) | F29: =SUM(F30:F32) | G29: =SUM(G30:G32) | H29: =SUM(H30:H32) | I29: =SUM(I30:I32) | J29: =SUM(J30:J32)
B30: Recebimentos de Clientes | J30: =SUM(D30:I30) | L30: =IF(COUNT(D30:I30)=0,"",IF(ABS(J30-Gabarito!J30)<0.5,"✔","✗"))
B31: Pagamentos a Fornecedores | J31: =SUM(D31:I31) | L31: =IF(COUNT(D31:I31)=0,"",IF(ABS(J31-Gabarito!J31)<0.5,"✔","✗"))
B32: Pagamentos de Despesas | J32: =SUM(D32:I32) | L32: =IF(COUNT(D32:I32)=0,"",IF(ABS(J32-Gabarito!J32)<0.5,"✔","✗"))
B33: INVESTIMENTOS | D33: =SUM(D34:D34) | E33: =SUM(E34:E34) | F33: =SUM(F34:F34) | G33: =SUM(G34:G34) | H33: =SUM(H34:H34) | I33: =SUM(I34:I34) | J33: =SUM(J34:J34)
B34: Aquisição de Imobilizado | J34: =SUM(D34:I34) | L34: =IF(COUNT(D34:I34)=0,"",IF(ABS(J34-Gabarito!J34)<0.5,"✔","✗"))
B35: FINANCIAMENTOS | D35: =SUM(D36:D36) | E35: =SUM(E36:E36) | F35: =SUM(F36:F36) | G35: =SUM(G36:G36) | H35: =SUM(H36:H36) | I35: =SUM(I36:I36) | J35: =SUM(J36:J36)
B36: Ingresso de Capital | J36: =SUM(D36:I36) | L36: =IF(COUNT(D36:I36)=0,"",IF(ABS(J36-Gabarito!J36)<0.5,"✔","✗"))
B37: VARIAÇÃO NO CAIXA | D37: =D29+D33+D35 | E37: =E29+E33+E35 | F37: =F29+F33+F35 | G37: =G29+G33+G35 | H37: =H29+H33+H35 | I37: =I29+I33+I35 | J37: =J29+J33+J35
B38: Saldo inicial de caixa | J38: 0
B39: Saldo final de caixa | J39: =J38+J37
B41: Caixa final da DFC menos Caixa do BP (tem que dar zero) | J41: =J39-J6 | L41: =IF(J41=0,"✔ amarra","✗ não amarra")
B43: Indicadores (automáticos)
B44: Margem bruta | J44: =IF(J22=0,"",J24/J22)
B45: Margem líquida | J45: =IF(J22=0,"",J26/J22)
...

Sheet Gabarito
B1: Cafeteria Grão de Ouro | D1: Transações, por Número e Descrição
B2: Mês 1 | valores em R$ | D2: Integralização de capital de R$ 80.000 em dinheiro | E2: Compra à vista de máquina de espresso e mobiliário por R$ 30 | F2: Compra de café e insumos por R$ 24.000, metade à vista e met | G2: Venda de metade do estoque por R$ 27.000 à vista (custo de R | H2: Pagamento de salários e aluguel do mês, R$ 6.000 à vista | I2: Pagamento de metade do que devia aos fornecedores
B3: Balanço Patrimonial | C3: Balanço Inicial | D3: 1 | E3: 2 | F3: 3 | G3: 4 | H3: 5 | I3: 6 | J3: Balanço Final
B4: ATIVO
B5: Ativo Circulante
B6: Caixa | D6: 80000 | E6: -30000 | F6: -12000 | G6: 27000 | H6: -6000 | I6: -6000 | J6: =C6+SUM(D6:I6)
B7: Estoque | F7: 24000 | G7: -12000 | J7: =C7+SUM(D7:I7)
B8: Ativo Não Circulante
B9: Imobilizado | E9: 30000 | J9: =C9+SUM(D9:I9)
B10: Total do Ativo | C10: =SUM(C6:C9) | D10: =SUM(D6:D9) | E10: =SUM(E6:E9) | F10: =SUM(F6:F9) | G10: =SUM(G6:G9) | H10: =SUM(H6:H9) | I10: =SUM(I6:I9) | J10: =SUM(J6:J9)
B11: PASSIVO E PATRIM. LÍQUIDO
B12: Passivo Circulante:
B13: Contas a Pagar | F13: 12000 | I13: -6000 | J13: =C13+SUM(D13:I13)
B14: Patrimônio Líquido:
B15: Capital Social | D15: 80000 | J15: =C15+SUM(D15:I15)
B16: Lucros Acumulados | G16: 15000 | H16: -6000 | J16: =C16+SUM(D16:I16)
B17: Total Passivo e Patrim. Líquido | C17: =SUM(C12:C16) | D17: =SUM(D12:D16) | E17: =SUM(E12:E16) | F17: =SUM(F12:F16) | G17: =SUM(G12:G16) | H17: =SUM(H12:H16) | I17: =SUM(I12:I16) | J17: =SUM(J12:J16)
B19: Diferença, se houver (tem que dar zero) | C19: =C10-C17 | D19: =D10-D17 | E19: =E10-E17 | F19: =F10-F17 | G19: =G10-G17 | H19: =H10-H17 | I19: =I10-I17 | J19: =J10-J17
B21: Demonstração do Resultado | D21: 1 | E21: 2 | F21: 3 | G21: 4 | H21: 5 | I21: 6 | J21: Mês 1 | L21: Check
B22: Receita de Vendas | G22: 27000 | J22: =SUM(D22:I22)
B23: (-) Custo das Mercadorias Vendidas | G23: -12000 | J23: =SUM(D23:I23)
B24: (=) Lucro Bruto | D24: =SUM(D22:D23) | E24: =SUM(E22:E23) | F24: =SUM(F22:F23) | G24: =SUM(G22:G23) | H24: =SUM(H22:H23) | I24: =SUM(I22:I23) | J24: =SUM(J22:J23)
B25: (-) Despesas Operacionais | H25: -6000 | J25: =SUM(D25:I25)
B26: (=) EBIT e Lucro Líquido | D26: =SUM(D24:D25) | E26: =SUM(E24:E25) | F26: =SUM(F24:F25) | G26: =SUM(G24:G25) | H26: =SUM(H24:H25) | I26: =SUM(I24:I25) | J26: =SUM(J24:J25)
B28: Demonstração dos Fluxos de Caixa | D28: 1 | E28: 2 | F28: 3 | G28: 4 | H28: 5 | I28: 6 | J28: Mês 1
B29: OPERAÇÕES | D29: =SUM(D30:D32) | E29: =SUM(E30:E32) | F29: =SUM(F30:F32) | G29: =SUM(G30:G32) | H29: =SUM(H30:H32) | I29: =SUM(I30:I32) | J29: =SUM(J30:J32)
B30: Recebimentos de Clientes | G30: 27000 | J30: =SUM(D30:I30)
B31: Pagamentos a Fornecedores | F31: -12000 | I31: -6000 | J31: =SUM(D31:I31)
B32: Pagamentos de Despesas | H32: -6000 | J32: =SUM(D32:I32)
B33: INVESTIMENTOS | D33: =SUM(D34:D34) | E33: =SUM(E34:E34) | F33: =SUM(F34:F34) | G33: =SUM(G34:G34) | H33: =SUM(H34:H34) | I33: =SUM(I34:I34) | J33: =SUM(J34:J34)
B34: Aquisição de Imobilizado | E34: -30000 | J34: =SUM(D34:I34)
B35: FINANCIAMENTOS | D35: =SUM(D36:D36) | E35: =SUM(E36:E36) | F35: =SUM(F36:F36) | G35: =SUM(G36:G36) | H35: =SUM(H36:H36) | I35: =SUM(I36:I36) | J35: =SUM(J36:J36)
B36: Ingresso de Capital | D36: 80000 | J36: =SUM(D36:I36)
B37: VARIAÇÃO NO CAIXA | D37: =D29+D33+D35 | E37: =E29+E33+E35 | F37: =F29+F33+F35 | G37: =G29+G33+G35 | H37: =H29+H33+H35 | I37: =I29+I33+I35 | J37: =J29+J33+J35
B38: Saldo inicial de caixa | J38: 0
B39: Saldo final de caixa | J39: =J38+J37
B41: Caixa final da DFC menos Caixa do BP (tem que dar zero) | J41: =J39-J6
B43: Indicadores (automáticos)
B44: Margem bruta | J44: =IF(J22=0,"",J24/J22)
B45: Margem líquida | J45: =IF(J22=0,"",J26/J22)
...

Sheet Gabarito Equação
A1: Cafeteria Grão de Ouro | Efeito das transações na Equação do Balanço
A2: Uma linha por movimento: escreve a conta e o valor, com sinal. Transação que mexe em três contas do mesmo lado usa as três linhas. A coluna Check acusa se aquela transação fechou.
A4: Nº | B4: Descrição | C4: ATIVO | E4: = | F4: PASSIVO | H4: + | I4: PATRIMÔNIO LÍQUIDO | K4: Check
C5: conta | D5: valor | F5: conta | G5: valor | I5: conta | J5: valor
A6: 1 | B6: Integralização de capital de R$ 80.000 em dinheiro | C6: Caixa | D6: 80000 | E6: = | H6: + | I6: Capital Social | J6: 80000 | K6: =IF(COUNT(D6:D7,G6:G7,J6:J7)=0,"",IF(SUM(D6:D7)-SUM(G6:G7)-SUM(J6:J7)=0,"✔","✗"))
E7: = | H7: +
A8: 2 | B8: Compra à vista de máquina de espresso e mobiliário por R$ 30.000 | C8: Caixa | D8: -30000 | E8: = | H8: + | K8: =IF(COUNT(D8:D9,G8:G9,J8:J9)=0,"",IF(SUM(D8:D9)-SUM(G8:G9)-SUM(J8:J9)=0,"✔","✗"))
C9: Imobilizado | D9: 30000 | E9: = | H9: +
A10: 3 | B10: Compra de café e insumos por R$ 24.000, metade à vista e metade a prazo | C10: Caixa | D10: -12000 | E10: = | F10: Contas a Pagar | G10: 12000 | H10: + | K10: =IF(COUNT(D10:D11,G10:G11,J10:J11)=0,"",IF(SUM(D10:D11)-SUM(G10:G11)-SUM(J10:J11)=0,"✔","✗"))
C11: Estoque | D11: 24000 | E11: = | H11: +
A12: 4 | B12: Venda de metade do estoque por R$ 27.000 à vista (custo de R$ 12.000) | C12: Caixa | D12: 27000 | E12: = | H12: + | I12: Lucros Acumulados | J12: 15000 | K12: =IF(COUNT(D12:D13,G12:G13,J12:J13)=0,"",IF(SUM(D12:D13)-SUM(G12:G13)-SUM(J12:J13)=0,"✔","✗"))
C13: Estoque | D13: -12000 | E13: = | H13: +
A14: 5 | B14: Pagamento de salários e aluguel do mês, R$ 6.000 à vista | C14: Caixa | D14: -6000 | E14: = | H14: + | I14: Lucros Acumulados | J14: -6000 | K14: =IF(COUNT(D14:D15,G14:G15,J14:J15)=0,"",IF(SUM(D14:D15)-SUM(G14:G15)-SUM(J14:J15)=0,"✔","✗"))
E15: = | H15: +
A16: 6 | B16: Pagamento de metade do que devia aos fornecedores | C16: Caixa | D16: -6000 | E16: = | F16: Contas a Pagar | G16: -6000 | H16: + | K16: =IF(COUNT(D16:D17,G16:G17,J16:J17)=0,"",IF(SUM(D16:D17)-SUM(G16:G17)-SUM(J16:J17)=0,"✔","✗"))
E17: = | H17: +
