Workbook

Sheet Premissas
A1: CASO MARCUS DENT: demonstracoes financeiras de janeiro/2024
A2: Valores em R$. Legenda: | B2: azul = input do caso | C2: preto = formula | D2: verde = link entre abas
A4: Abertura (31/12/2023)
A5: Emprestimo microcredito (principal) | B5: 54000
A6: Taxa de juros mensal | B6: 0.02
A7: Equipamentos (comprados com o emprestimo) | B7: =B5 -> 54000
A8: Vida util dos equipamentos (meses) | B8: 36
A9: Capital inicial (economias depositadas) | B9: 10000
A11: Janeiro/2024
A12: Servicos prestados no mes | B12: 8000
A13: % recebido a vista | B13: 0.2
A14: Adiantamento recebido (servicos de marco) | B14: 2000
A15: Aluguel pago no mes | B15: 2200
A16: Meses cobertos pelo aluguel pago | B16: 2
A17: Compra de materiais (a vista) | B17: 3000
A18: Estoque de materiais em 31/01 | B18: 1300
A19: Salarios e encargos do mes (pagos em fevereiro) | B19: 500
A21: Derivados
A22: Depreciacao mensal | B22: =B7/B8 -> 1500
A23: Juros do mes | B23: =B5*B6 -> 1080
A24: Aluguel de competencia do mes | B24: =B15/B16 -> 1100
A25: Materiais consumidos | B25: =B17-B18 -> 1700
A26: Recebido a vista de servicos | B26: =B12*B13 -> 1600
A27: Servicos a receber (clientes) | B27: =B12-B26 -> 6400
A28: Despesa antecipada de aluguel (fevereiro) | B28: =B15-B24 -> 1100

Sheet Transacoes
A1: Efeito de cada transacao de janeiro/2024 no Balanco, na DRE e no Caixa
B2: BP inicial 31/12/23 | C2: T1a Servicos | D2: T1b Adiantamento | E2: T2 Aluguel | F2: T3 Materiais | G2: T4 Salarios | H2: T5 Depreciacao | I2: T6 Juros | J2: BP final 31/01/24
B3: Emprestimo de 54.000 vira equipamentos; economias de 10.000 viram capital | C3: Presta 8.000, recebe 20% a vista, 80% fica a receber | D3: Recebe 2.000 por servicos que so presta em marco | E3: Paga 2.200 de aluguel de janeiro e fevereiro | F3: Compra 3.000 a vista, sobra 1.300 em estoque | G3: Salario de 500 do mes, pago em fevereiro | H3: 54.000 / 36 meses | I3: 2% x 54.000, pagos so no fim de 2 anos | J3: Soma das colunas
A4: ATIVO
A5: Caixa e bancos | B5: =Premissas!B9 -> 10000 | C5: =Premissas!B26 -> 1600 | D5: =Premissas!B14 -> 2000 | E5: =-Premissas!B15 -> -2200 | F5: =-Premissas!B17 -> -3000 | J5: =SUM(B5:I5) -> 8400
A6: Clientes (duplicatas a receber) | C6: =Premissas!B27 -> 6400 | J6: =SUM(B6:I6) -> 6400
A7: Estoque de materiais | F7: =Premissas!B18 -> 1300 | J7: =SUM(B7:I7) -> 1300
A8: Despesas antecipadas (aluguel de fevereiro) | E8: =Premissas!B28 -> 1100 | J8: =SUM(B8:I8) -> 1100
A9: Ativo circulante | B9: =SUM(B5:B8) -> 10000 | C9: =SUM(C5:C8) -> 8000 | D9: =SUM(D5:D8) -> 2000 | E9: =SUM(E5:E8) -> -1100 | F9: =SUM(F5:F8) -> -1700 | G9: =SUM(G5:G8) -> 0 | H9: =SUM(H5:H8) -> 0 | I9: =SUM(I5:I8) -> 0 | J9: =SUM(J5:J8) -> 17200
A10: Equipamentos | B10: =Premissas!B7 -> 54000 | J10: =SUM(B10:I10) -> 54000
A11: (-) Depreciacao acumulada | H11: =-Premissas!B22 -> -1500 | J11: =SUM(B11:I11) -> -1500
A12: Ativo nao circulante (imobilizado liquido) | B12: =B10+B11 -> 54000 | C12: =C10+C11 -> 0 | D12: =D10+D11 -> 0 | E12: =E10+E11 -> 0 | F12: =F10+F11 -> 0 | G12: =G10+G11 -> 0 | H12: =H10+H11 -> -1500 | I12: =I10+I11 -> 0 | J12: =J10+J11 -> 52500
A13: TOTAL DO ATIVO | B13: =B9+B12 -> 64000 | C13: =C9+C12 -> 8000 | D13: =D9+D12 -> 2000 | E13: =E9+E12 -> -1100 | F13: =F9+F12 -> -1700 | G13: =G9+G12 -> 0 | H13: =H9+H12 -> -1500 | I13: =I9+I12 -> 0 | J13: =J9+J12 -> 69700
A15: PASSIVO
A16: Salarios a pagar | G16: =Premissas!B19 -> 500 | J16: =SUM(B16:I16) -> 500
A17: Receita antecipada (adiantamento de clientes) | D17: =Premissas!B14 -> 2000 | J17: =SUM(B17:I17) -> 2000
A18: Passivo circulante | B18: =SUM(B16:B17) -> 0 | C18: =SUM(C16:C17) -> 0 | D18: =SUM(D16:D17) -> 2000 | E18: =SUM(E16:E17) -> 0 | F18: =SUM(F16:F17) -> 0 | G18: =SUM(G16:G17) -> 500 | H18: =SUM(H16:H17) -> 0 | I18: =SUM(I16:I17) -> 0 | J18: =SUM(J16:J17) -> 2500
A19: Emprestimo a pagar (vence dez/2025) | B19: =Premissas!B5 -> 54000 | J19: =SUM(B19:I19) -> 54000
A20: Juros a pagar (vencem com o principal) | I20: =Premissas!B23 -> 1080 | J20: =SUM(B20:I20) -> 1080
A21: Passivo nao circulante | B21: =B19+B20 -> 54000 | C21: =C19+C20 -> 0 | D21: =D19+D20 -> 0 | E21: =E19+E20 -> 0 | F21: =F19+F20 -> 0 | G21: =G19+G20 -> 0 | H21: =H19+H20 -> 0 | I21: =I19+I20 -> 1080 | J21: =J19+J20 -> 55080
A22: TOTAL DO PASSIVO | B22: =B18+B21 -> 54000 | C22: =C18+C21 -> 0 | D22: =D18+D21 -> 2000 | E22: =E18+E21 -> 0 | F22: =F18+F21 -> 0 | G22: =G18+G21 -> 500 | H22: =H18+H21 -> 0 | I22: =I18+I21 -> 1080 | J22: =J18+J21 -> 57580
A24: PATRIMONIO LIQUIDO
A25: Capital social | B25: =Premissas!B9 -> 10000 | J25: =SUM(B25:I25) -> 10000
A26: Lucros acumulados (resultado do mes) | B26: 0 | C26: =C39 -> 8000 | D26: =D39 -> 0 | E26: =E39 -> -1100 | F26: =F39 -> -1700 | G26: =G39 -> -500 | H26: =H39 -> -1500 | I26: =I39 -> -1080 | J26: =SUM(B26:I26) -> 2120
A27: TOTAL DO PL | B27: =B25+B26 -> 10000 | C27: =C25+C26 -> 8000 | D27: =D25+D26 -> 0 | E27: =E25+E26 -> -1100 | F27: =F25+F26 -> -1700 | G27: =G25+G26 -> -500 | H27: =H25+H26 -> -1500 | I27: =I25+I26 -> -1080 | J27: =J25+J26 -> 12120
A28: PASSIVO + PL | B28: =B22+B27 -> 64000 | C28: =C22+C27 -> 8000 | D28: =D22+D27 -> 2000 | E28: =E22+E27 -> -1100 | F28: =F22+F27 -> -1700 | G28: =G22+G27 -> 0 | H28: =H22+H27 -> -1500 | I28: =I22+I27 -> 0 | J28: =J22+J27 -> 69700
A29: Check: Ativo - (Passivo + PL) | B29: =B13-B28 -> 0 | C29: =C13-C28 -> 0 | D29: =D13-D28 -> 0 | E29: =E13-E28 -> 0 | F29: =F13-F28 -> 0 | G29: =G13-G28 -> 0 | H29: =H13-H28 -> 0 | I29: =I13-I28 -> 0 | J29: =J13-J28 -> 0
A31: DRE (regime de competencia)
A32: Receita de servicos | C32: =Premissas!B12 -> 8000 | J32: =SUM(B32:I32) -> 8000
A33: (-) Aluguel | E33: =-Premissas!B24 -> -1100 | J33: =SUM(B33:I33) -> -1100
A34: (-) Salarios e encargos | G34: =-Premissas!B19 -> -500 | J34: =SUM(B34:I34) -> -500
A35: (-) Materiais consumidos | F35: =-Premissas!B25 -> -1700 | J35: =SUM(B35:I35) -> -1700
A36: (-) Depreciacao dos equipamentos | H36: =-Premissas!B22 -> -1500 | J36: =SUM(B36:I36) -> -1500
A37: Resultado operacional (EBIT) | C37: =SUM(C32:C36) -> 8000 | D37: =SUM(D32:D36) -> 0 | E37: =SUM(E32:E36) -> -1100 | F37: =SUM(F32:F36) -> -1700 | G37: =SUM(G32:G36) -> -500 | H37: =SUM(H32:H36) -> -1500 | I37: =SUM(I32:I36) -> 0 | J37: =SUM(J32:J36) -> 3200
A38: (-) Juros do emprestimo (despesa financeira) | I38: =-Premissas!B23 -> -1080 | J38: =SUM(B38:I38) -> -1080
A39: LUCRO LIQUIDO DO MES | C39: =C37+C38 -> 8000 | D39: =D37+D38 -> 0 | E39: =E37+E38 -> -1100 | F39: =F37+F38 -> -1700 | G39: =G37+G38 -> -500 | H39: =H37+H38 -> -1500 | I39: =I37+I38 -> -1080 | J39: =J37+J38 -> 2120
A40: Check: lucro da DRE - variacao de lucros acumulados | J40: =J39-(J26-B26) -> 0
A42: CAIXA (regime de caixa)
A43: Entradas | C43: =Premissas!B26 -> 1600 | D43: =Premissas!B14 -> 2000 | J43: =SUM(B43:I43) -> 3600
A44: Saidas | E44: =-Premissas!B15 -> -2200 | F44: =-Premissas!B17 -> -3000 | J44: =SUM(B44:I44) -> -5200
...

Sheet Comparativo
A1: Tabela comparativa: Fluxo de Caixa (regime de caixa) x DRE (regime de competencia)
B3: Fluxo de Caixa (Regime de Caixa) | C3: DRE (Regime de Competencia)
A4: Receitas/Entradas
A5: Servicos | B5: =Premissas!B26 -> 1600 | C5: =Premissas!B12 -> 8000
A6: Adiantam. Serv. | B6: =Premissas!B14 -> 2000 | C6: 0
A7: Subtotal | B7: =SUM(B5:B6) -> 3600 | C7: =SUM(C5:C6) -> 8000
A8: Despesas/Saidas
A9: Aluguel | B9: =-Premissas!B15 -> -2200 | C9: =-Premissas!B24 -> -1100
A10: Salarios | B10: 0 | C10: =-Premissas!B19 -> -500
A11: Material | B11: =-Premissas!B17 -> -3000 | C11: =-Premissas!B25 -> -1700
A12: Depreciacao do Equipamento | B12: 0 | C12: =-Premissas!B22 -> -1500
A13: Juros | B13: 0 | C13: =-Premissas!B23 -> -1080
A14: Subtotal | B14: =SUM(B9:B13) -> -5200 | C14: =SUM(C9:C13) -> -5880
A15: Lucro / Variacao no Caixa | B15: =B7+B14 -> -1600 | C15: =C7+C14 -> 2120
A17: Check contra a aba Transacoes (deve dar zero) | B17: =B15-Transacoes!J45 -> 0 | C17: =C15-Transacoes!J39 -> 0
A19: Lucro menos variacao de caixa (explicado na aba Reconciliacao) | C19: =C15-B15 -> 3720

Sheet Reconciliacao
A1: Reconciliacao: do lucro (competencia) a variacao de caixa (regime de caixa), metodo indireto
A3: Lucro liquido do mes | B3: =Transacoes!J39 -> 2120
A4: (+) Despesas que nao sairam do caixa
A5: Depreciacao | B5: =-Transacoes!J36 -> 1500
A6: Juros provisionados e nao pagos (aumento de juros a pagar) | B6: =Transacoes!J20-Transacoes!B20 -> 1080
A7: (-/+) Variacao do capital de giro
A8: (-) Aumento de clientes | B8: =-(Transacoes!J6-Transacoes!B6) -> -6400
A9: (-) Aumento de estoque | B9: =-(Transacoes!J7-Transacoes!B7) -> -1300
A10: (-) Aumento de despesas antecipadas | B10: =-(Transacoes!J8-Transacoes!B8) -> -1100
A11: (+) Aumento de salarios a pagar | B11: =Transacoes!J16-Transacoes!B16 -> 500
A12: (+) Aumento de receita antecipada | B12: =Transacoes!J17-Transacoes!B17 -> 2000
A13: Caixa gerado (utilizado) nas operacoes, FCO | B13: =SUM(B3:B12) -> -1600
A14: Caixa de investimento em janeiro (equipamentos comprados em 31/12) | B14: 0
A15: Caixa de financiamento em janeiro (emprestimo e capital em 31/12) | B15: 0
A16: Variacao de caixa (indireto) | B16: =B13+B14+B15 -> -1600
A17: Variacao de caixa pelo metodo direto (aba Transacoes) | B17: =Transacoes!J45 -> -1600
A18: Check: indireto - direto (deve dar zero) | B18: =B16-B17 -> 0
