Workbook

Sheet QUIZ
B3: Qual é o preço que uma pessoa deveria pagar por um título Tesouro Prefixado, conhecido como LTN - Letra do Tesouro Nacional, que está disponível na página internet do TESOURODIRETO, e negociado com rendimento anualizado até o vencimento de 15,28 % e vencimento em 314 dias úteis?
B5: Valor face | C5: 1000 | D5: R$ | F5: YTM | G5: 0.1528 | I5: fórmula taxa de retorno
B6: i | C6: 0.1528 | D6: a.a. | F6: vencimento | G6: 314 | I6: TR = (VF/VP)^(ano/n) -1
B7: n | C7: 314 | D7: dias úteis | F7: vf | G7: 1000 | I7: TR = (VF-VP)/VP
B9: Preço | C9: =C5/(1+C6)^(C7/252) -> 837.63072 | D9: R$ | F9: preço | G9: =G7/(1+G5)^(G6/252) -> 837.63072 | I9: fórmula do preço de um título
I10: P = VN/(1+YTM)^n/ano
B12: No app de uma assessoria de investimentos há uma LTN (Letra do Tesouro Nacional) , com vencimento em 217 dias úteis, que é oferecida por R$ 829,93 . Qual é o retorno anualizado até o vencimento que uma investidora obteria se adquirisse esta LTN?
B14: Valor face | C14: 1000 | D14: R$ | F14: vf | G14: 1000
B15: Preço | C15: 829.93 | D15: R$ | F15: vencimento | G15: 217
B16: n | C16: 217 | D16: dias úteis | F16: preço | G16: 829.93
F17: retorno | G17: =(G14/G16)^(252/G15)-1 -> 0.2416991
B19: Retorno | C19: =(C14/C15)^(252/C16)-1 -> 0.2416991 | D19: ao ano
B22: Martha, que trabalha em uma consultoria macroeconômica, prevê que os juros vão cair nas próximas reuniões do COPOM. Shirley viu a previsão e decidiu investir agora em Tesouro Pré-fixado com Juros Semestrais (NTN-F) com YTM de 14,30% ao ano e vencimento em 710 dias úteis. Qual o preço dessa NTN-F? Considere que a NTN-F paga os cupons em 80, 206, 332, 458, 584 e 710 dias úteis.
B24: YTM | C24: 0.143 | D24: a.a | F24: Dias úteis | G24: Fluxo caixa | H24: VP | J24: YTM | K24: 0.143 | M24: data | N24: cupom | O24: vp
F25: 80 | G25: =C27*C28 -> 48.808848 | H25: =G25/(1+C24)^(F25/252) -> 46.781181 | J25: n | K25: 710 | M25: 80 | N25: =$K$28*$K$26 -> 48.808848 | O25: =N25/(1+$K$24)^(M25/252) -> 46.781181
B26: Taxa cupom | C26: 0.1 | D26: a.a | F26: =+F25+126 -> 206 | G26: =C27*C28 -> 48.808848 | H26: =G26/(1+C24)^(F26/252) -> 43.757053 | J26: face | K26: 1000 | M26: 206 | N26: =$K$28*$K$26 -> 48.808848 | O26: =N26/(1+$K$24)^(M26/252) -> 43.757053
B27: Taxa cupom | C27: =(1+C26)^(1/2)-1 -> 0.048808848 | D27: a.s. | F27: =+F26+126 -> 332 | G27: =C27*C28 -> 48.808848 | H27: =G27/(1+C24)^(F27/252) -> 40.928418 | J27: taxa c ano | K27: 0.1 | M27: 332 | N27: =$K$28*$K$26 -> 48.808848 | O27: =N27/(1+$K$24)^(M27/252) -> 40.928418
B28: Valor face | C28: 1000 | D28: $ | F28: =+F27+126 -> 458 | G28: =C27*C28 -> 48.808848 | H28: =G28/(1+C24)^(F28/252) -> 38.282636 | J28: taxa c sem | K28: =(1+K27)^(1/2)-1 -> 0.048808848 | M28: 458 | N28: =$K$28*$K$26 -> 48.808848 | O28: =N28/(1+$K$24)^(M28/252) -> 38.282636
F29: =+F28+126 -> 584 | G29: =C27*C28 -> 48.808848 | H29: =G29/(1+C24)^(F29/252) -> 35.807889 | J29: preço | K29: =SUM(O25:O30) -> 925.26031 | M29: 584 | N29: =$K$28*$K$26 -> 48.808848 | O29: =N29/(1+$K$24)^(M29/252) -> 35.807889
B30: Preço | C30: =SUM(H25:H30) -> 925.26031 | D30: R$ | F30: =+F29+126 -> 710 | G30: =C27*C28+C28 -> 1048.8088 | H30: =G30/(1+C24)^(F30/252) -> 719.70313 | M30: 710 | N30: =$K$28*$K$26+K26 -> 1048.8088 | O30: =N30/(1+$K$24)^(M30/252) -> 719.70313
B33: Shondra investiu no CDB do banco que remunera 260 % da taxa DI. Depois do investimento no CDB, a taxa DI nos primeiros 40 dias úteis foi de 19,96 % ao ano, e nos próximos 25 dias úteis a taxa DI foi de 21,15 % ao ano. Ao final desse segundo período, Shondra resgatou o CDB. Qual foi a taxa bruta de retorno que Shondra terá no período total de aplicação no CDB?
B35: Remuneração | C35: 2.6 | D35: da taxa DI | H35: taxa di | I35: 2.6
B36: n1 | C36: 40 | D36: d.u. | H36: tr | I36: =(1+J39*I35)*(1+J40*I35)-1 -> 0.12997016
B37: Taxa DI (1) | C37: 0.1996 | D37: ao ano | E37: ----> | F37: =(1+C37)^(1/252)-1 -> 0.0007224361 | G37: ao dia
B38: n2 | C38: 25 | D38: d.u. | H38: n | I38: taxa ano | J38: taxa dia
B39: Taxa DI (2) | C39: 0.2115 | D39: ao ano | E39: ----> | F39: =(1+C39)^(1/252)-1 -> 0.00076163617 | G39: ao dia | H39: 40 | I39: 0.1996 | J39: =(1+I39)^(H39/252)-1 -> 0.029308287
H40: 25 | I40: 0.2115 | J40: =(1+I40)^(H40/252)-1 -> 0.019215952
B41: Taxa de retorno | C41: =((1+F37*C35)^C36)*((1+F39*C35)^C38)-1 -> 0.13260499 | D41: no período
B44: Uma organização humanitária recebeu uma doação, e investiu R$ 148.671,20 do valor recebido em um título do governo brasileiro que remunera a taxa SELIC. Passados 148 dias úteis, a partir do investimento feito inicialmente, a organização verificou quanto tinha de saldo nesse investimento. Considerando que durante todo período a taxa SELIC over (ou de mercado) foi 23,30 % ao ano, calcule o valor do saldo do investimento no final dos 148 dias úteis.
B46: Investimento | C46: 148671.2 | D46: R$ | F46: investimento | G46: 148671.2
B47: n | C47: 148 | D47: d.u. | F47: n | G47: 148
B48: Taxa SELIC over | C48: 0.233 | D48: ao ano | F48: selic | G48: 0.233
F49: vf | G49: =G46*(1+G48)^(G47/252)-1 -> 168130.7
B50: Saldo | C50: =C46*(1+C48)^(C47/252) -> 168131.7 | D50: R$
B53: Xavier deve pagar R$ 71.789,06 , daqui 9 meses, que é a primeira parcela do seu iate recém adquirido. Quanto em Reais Xavier precisa investir hoje em uma aplicação que remunera 100% da taxa DI para honrar a parcela? Considere que a taxa DI no período foi sempre igual a 22,46 % ao ano. Também considere que todos meses tem o mesmo número de dias úteis.
B55: Dívida | C55: 71789.06 | D55: R$ | F55: vf | G55: 71789.06
B56: n | C56: 9 | D56: meses | F56: n | G56: 9
B57: Taxa DI | C57: 0.2246 | D57: ao ano | F57: taxa di | G57: 0.2246
F58: preço | G58: =G55/(1+G57)^(21*G56/252) -> 61668.385
B59: Saldo | C59: =C55/(1+C57)^(C56/12) -> 61668.385 | D59: R$
...

Sheet FeriadosHolidays
A1: 36892
A2: 36948
A3: 36949
A4: 36994
A5: 37002
A6: 37012
A7: 37056
A8: 37141
A9: 37176
A10: 37197
A11: 37210
A12: 37250
... A1264: 73044
