Workbook

Sheet LeiaMe
B2: Treino: DFs principais (ContabilidadeFinanceira, 10.08.2026)
B4: Como usar:
B5: 1. Célula AMARELA = você preenche. Texto azul sem fundo = dado do caso, não mexe.
B6: 2. Abas B e C corrigem sozinhas: a coluna Check mostra ✔ ou ✗ comparando com a aba Gabarito.
B7: 3. Abas A e D são discursivas: escreve tua resposta e só depois compara com o Gabarito.
B8: 4. Convenção de sinais nos casos numéricos: despesas e saídas de caixa entram NEGATIVAS.
B9: 5. Não abre a aba Gabarito antes de terminar. A correção automática já te diz se acertou.
B11: Ordem sugerida (tempo total ~40 min): A conceitos, B classificação, C caso 1, C caso 2, D pegadinhas.
B12: Exemplo de como funciona: a primeira linha da aba B_Classificacao já vem respondida como demonstração.

Sheet Gabarito
B1: Gabarito
E2: Esperado C_Caso1 | F2: Esperado C_Caso2 | G2: Bloco D | H2: Bloco A
D3: C_Caso1: Receita líquida | E3: =C_Caso1!$C$5 -> 1000
D4: C_Caso1: (-) CMV | E4: =-C_Caso1!$C$6 -> -600 | G4: D1. Não. Lucro operacional conceitual vem ANTES do resultado financeiro. O nome da linha não manda; recalcula: lucro bruto menos despesas operacionais. | H4: A1. RA: o que aconteceu e pra onde vamos, na voz da gestão. BP: onde o dinheiro está aplicado e de onde veio. DRE: resultado das operações do período. DFC: principais entradas e saídas de caixa.
C5: BP | D5: C_Caso1: = Lucro bruto | E5: =C_Caso1!$C$5-C_Caso1!$C$6 -> 400 | G5: D2. Não. Investimentos em análise são o ativo (aplicações). Capital social e reservas são origens, lado direito. | H5: A2. BP é foto de uma data; DRE e DFC são filmes de um período. Posição vs desempenho: comparar duas fotos do BP exige os filmes pra explicar o que mudou.
C6: BP | D6: C_Caso1: (-) Despesas de vendas | E6: =-C_Caso1!$C$7 -> -120 | G6: D3. Não direto. A receita líquida da cerveja já perdeu ~40% em tributo antes da margem. Comparação entre setores exige olhar o que saiu da receita. | H6: A3. Os dois lados são a mesma coisa vista de ângulos diferentes: esquerdo mostra onde o dinheiro está aplicado, direito mostra de onde veio (terceiros ou sócios). Todo recurso aplicado tem origem; se não bate, tem erro.
C7: DRE | D7: C_Caso1: (-) Despesas administrativas | E7: =-C_Caso1!$C$8 -> -80 | G7: D4. Na DFC, linha do fluxo de caixa das atividades operacionais (FCO). Geração de caixa sem FCO forte é marketing. | H7: A4. Por função responde 'pra que gastei': lucro bruto isola o valor agregado da atividade-fim, EBIT isola a operação inteira, LL isola o que sobra pro acionista depois de banco e governo. Por natureza responderia 'com que gastei' e misturaria as camadas.
C8: DFC | D8: C_Caso1: = EBIT | E8: =C_Caso1!$C$5-C_Caso1!$C$6-C_Caso1!$C$7-C_Caso1!$C$8 -> 200 | G8: D5. Lucro do ano: quase zero (só D&A de dezembro, se houver). Caixa: -200 no FCI. Próximos anos: D&A anual reduzindo o lucro ao longo da vida útil. | H8: A5. DRE é competência, caixa é sobrevivência. Varejista que vende a prazo longo e estoca agressivo mostra lucro alto com FCO fraco; sem caixa pra pagar fornecedor, quebra com DRE bonita.
C9: BP | D9: C_Caso1: (+/-) Resultado financeiro | E9: =C_Caso1!$C$11-C_Caso1!$C$10 -> -30 | H9: A6. Baixo: é a gestão escrevendo sobre si mesma, sem o rigor de auditoria das DFs. Serve de contexto e guia de leitura; toda afirmação se confere contra os números.
C10: DFC | D10: C_Caso1: = LAIR | E10: =C_Caso1!$C$5-C_Caso1!$C$6-C_Caso1!$C$7-C_Caso1!$C$8+C_Caso1!$C$11-C_Caso1!$C$10 -> 170 | H10: A7. Consolidado é o grupo econômico (visão econômica); controladora é a pessoa jurídica sozinha (visão jurídica). Holding 'Participações' sozinha não opera nada.
C11: RA | D11: C_Caso1: (-) IR | E11: =-(C_Caso1!$C$5-C_Caso1!$C$6-C_Caso1!$C$7-C_Caso1!$C$8+C_Caso1!$C$11-C_Caso1!$C$10)*C_Caso1!$C$12 -> -51
C12: Notas Explicativas | D12: C_Caso1: = Lucro líquido | E12: =(C_Caso1!$C$5-C_Caso1!$C$6-C_Caso1!$C$7-C_Caso1!$C$8+C_Caso1!$C$11-C_Caso1!$C$10)*(1-C_Caso1!$C$12) -> 119
D13: C_Caso1: Margem bruta | E13: =(C_Caso1!$C$5-C_Caso1!$C$6)/C_Caso1!$C$5 -> 0.4
D14: C_Caso1: Lucro líquido | E14: =(C_Caso1!$C$5-C_Caso1!$C$6-C_Caso1!$C$7-C_Caso1!$C$8+C_Caso1!$C$11-C_Caso1!$C$10)*(1-C_Caso1!$C$12) -> 119
D15: C_Caso1: (+) D&A | E15: =C_Caso1!$C$9 -> 30
D16: C_Caso1: (-) Aumento de contas a receber | E16: =-C_Caso1!$C$13 -> -50
C17: Custo | D17: C_Caso1: (-) Aumento de estoques | E17: =-C_Caso1!$C$14 -> -40
C18: Despesa de vendas | D18: C_Caso1: (+) Aumento de fornecedores | E18: =C_Caso1!$C$15 -> 20
C19: Despesa administrativa | D19: C_Caso1: = FCO | E19: =((C_Caso1!$C$5-C_Caso1!$C$6-C_Caso1!$C$7-C_Caso1!$C$8+C_Caso1!$C$11-C_Caso1!$C$10)*(1-C_Caso1!$C$12))+C_Caso1!$C$9-C_Caso1!$C$13-C_Caso1!$C$14+C_Caso1!$C$15 -> 79
C20: Custo | D20: C_Caso1: = FCO | E20: =((C_Caso1!$C$5-C_Caso1!$C$6-C_Caso1!$C$7-C_Caso1!$C$8+C_Caso1!$C$11-C_Caso1!$C$10)*(1-C_Caso1!$C$12))+C_Caso1!$C$9-C_Caso1!$C$13-C_Caso1!$C$14+C_Caso1!$C$15 -> 79
C21: Despesa administrativa | D21: C_Caso1: FCI (capex) | E21: =-C_Caso1!$C$16 -> -100
C22: Custo | D22: C_Caso1: FCF (empréstimos e dividendos) | E22: =C_Caso1!$C$17-C_Caso1!$C$18-C_Caso1!$C$19 -> 30
C23: Despesa de vendas | D23: C_Caso1: = Variação do caixa | E23: =(((C_Caso1!$C$5-C_Caso1!$C$6-C_Caso1!$C$7-C_Caso1!$C$8+C_Caso1!$C$11-C_Caso1!$C$10)*(1-C_Caso1!$C$12))+C_Caso1!$C$9-C_Caso1!$C$13-C_Caso1!$C$14+C_Caso1!$C$15)+(-C_Caso1!$C$16)+(C_Caso1!$C$17-C_Caso1!$C$18-C_Caso1!$C$19) -> 9
C24: Custo | D24: C_Caso1: Caixa final | E24: =((((C_Caso1!$C$5-C_Caso1!$C$6-C_Caso1!$C$7-C_Caso1!$C$8+C_Caso1!$C$11-C_Caso1!$C$10)*(1-C_Caso1!$C$12))+C_Caso1!$C$9-C_Caso1!$C$13-C_Caso1!$C$14+C_Caso1!$C$15)+(-C_Caso1!$C$16)+(C_Caso1!$C$17-C_Caso1!$C$18-C_Caso1!$C$19))+C_Caso1!$C$20 -> 50
D25: C_Caso1: Δ Caixa | E25: =(((C_Caso1!$C$5-C_Caso1!$C$6-C_Caso1!$C$7-C_Caso1!$C$8+C_Caso1!$C$11-C_Caso1!$C$10)*(1-C_Caso1!$C$12))+C_Caso1!$C$9-C_Caso1!$C$13-C_Caso1!$C$14+C_Caso1!$C$15)+(-C_Caso1!$C$16)+(C_Caso1!$C$17-C_Caso1!$C$18-C_Caso1!$C$19) -> 9
D26: C_Caso1: Δ Contas a receber | E26: =C_Caso1!$C$13 -> 50
D27: C_Caso1: Δ Estoques | E27: =C_Caso1!$C$14 -> 40
D28: C_Caso1: Δ Imobilizado (capex menos D&A) | E28: =C_Caso1!$C$16-C_Caso1!$C$9 -> 70
C29: FCI | D29: C_Caso1: = Δ Ativo total | E29: =((((C_Caso1!$C$5-C_Caso1!$C$6-C_Caso1!$C$7-C_Caso1!$C$8+C_Caso1!$C$11-C_Caso1!$C$10)*(1-C_Caso1!$C$12))+C_Caso1!$C$9-C_Caso1!$C$13-C_Caso1!$C$14+C_Caso1!$C$15)+(-C_Caso1!$C$16)+(C_Caso1!$C$17-C_Caso1!$C$18-C_Caso1!$C$19))+C_Caso1!$C$13+C_Caso1!$C$14+C_Caso1!$C$16-C_Caso1!$C$9 -> 169
C30: FCO | D30: C_Caso1: Δ Fornecedores | E30: =C_Caso1!$C$15 -> 20
C31: FCF | D31: C_Caso1: Δ Empréstimos | E31: =C_Caso1!$C$17-C_Caso1!$C$18 -> 60
C32: FCF | D32: C_Caso1: Δ PL (LL menos dividendos) | E32: =((C_Caso1!$C$5-C_Caso1!$C$6-C_Caso1!$C$7-C_Caso1!$C$8+C_Caso1!$C$11-C_Caso1!$C$10)*(1-C_Caso1!$C$12))-C_Caso1!$C$19 -> 89
C33: FCI | D33: C_Caso1: = Δ Passivo + PL | E33: =C_Caso1!$C$15+C_Caso1!$C$17-C_Caso1!$C$18+((C_Caso1!$C$5-C_Caso1!$C$6-C_Caso1!$C$7-C_Caso1!$C$8+C_Caso1!$C$11-C_Caso1!$C$10)*(1-C_Caso1!$C$12))-C_Caso1!$C$19 -> 169
B34: Pagamento a fornecedores | C34: FCO | D34: C_Caso1: resposta discursiva C6 | E34: Lucro (119) maior que FCO (79). A diferença é capital de giro: financiou cliente (+50 a receber) e estocou (+40), devolvendo só 20 via fornecedores. Cresceu consumindo caixa, padrão de expansão. | F34: LL 182 e FCO 162, mas capex de 120 mais FCF de -90 (amortizou 40 e distribuiu 50) consomem 210. Variação de caixa -48: a empresa lucrou, gerou caixa operacional, e mesmo assim queimou caixa porque investiu e devolveu dinheiro a credor e acionista ao mesmo tempo.
B35: Recompra de ações | C35: FCF
B36: Aquisição de uma empresa concorrente | C36: FCI

Sheet A_Conceitos
B1: Bloco A: questões centrais (responde em 2 a 4 frases, estilo QC da professora)
B3: Pergunta | C3: Sua resposta
A4: 1 | B4: Quais são as 4 DFs principais e que pergunta do negócio cada uma responde?
A5: 2 | B5: Balanço é foto ou filme? E a DRE? E a DFC? Por que essa distinção importa na análise?
A6: 3 | B6: Por que existe a equação Ativo = Passivo + PL? O que significa dizer que não existe aplicação sem origem?
A7: 4 | B7: Por que a DRE brasileira é organizada por função (atividade-fim, meio, financeira) e não por natureza do gasto? O que cada subtotal isola?
A8: 5 | B8: Se a DRE já mostra o resultado, por que a DFC existe? Dá um exemplo de empresa com lucro alto e caixa ruim.
A9: 6 | B9: Qual o grau de isenção do Relatório da Administração e como isso muda o jeito de usar ele?
A10: 7 | B10: Por que olhamos sempre a coluna consolidado e não a controladora?

Sheet B_Classificacao
B1: Bloco B: classificação rápida (dropdown na coluna Resposta, correção automática)
B3: B1. Em qual relatório você procura cada informação?
A4: # | B4: Item | C4: Resposta | D4: Check
A5: ex | B5: EXEMPLO: quanto a empresa tem de caixa hoje | C5: BP | D5: =IF(C5="","",IF(C5=Gabarito!C5,"✔","✗")) -> ✔
A6: 1 | B6: Quanto a empresa deve a bancos hoje | D6: =IF(C6="","",IF(C6=Gabarito!C6,"✔","✗"))
A7: 2 | B7: Quanto ela gastou pra fabricar o que vendeu no ano | D7: =IF(C7="","",IF(C7=Gabarito!C7,"✔","✗"))
A8: 3 | B8: Quanto pagou de dividendos no ano | D8: =IF(C8="","",IF(C8=Gabarito!C8,"✔","✗"))
A9: 4 | B9: Se o estoque cresceu em relação ao ano passado | D9: =IF(C9="","",IF(C9=Gabarito!C9,"✔","✗"))
A10: 5 | B10: Quanto caixa a operação gerou no ano | D10: =IF(C10="","",IF(C10=Gabarito!C10,"✔","✗"))
A11: 6 | B11: O guidance de expansão pros próximos anos | D11: =IF(C11="","",IF(C11=Gabarito!C11,"✔","✗"))
A12: 7 | B12: Detalhe de como uma linha do balanço foi calculada | D12: =IF(C12="","",IF(C12=Gabarito!C12,"✔","✗"))
C13: Acertos: | D13: =COUNTIF(D6:D12,"✔")&" / 7" -> 0 / 7
B15: B2. Custo ou despesa (e de qual tipo)?
A16: # | B16: Item | C16: Resposta | D16: Check
A17: 0 | B17: Salário do soldador na fábrica da Duratex | D17: =IF(C17="","",IF(C17=Gabarito!C17,"✔","✗"))
A18: 1 | B18: Salário da equipe de loja da Vivara | D18: =IF(C18="","",IF(C18=Gabarito!C18,"✔","✗"))
A19: 2 | B19: Salário do CFO | D19: =IF(C19="","",IF(C19=Gabarito!C19,"✔","✗"))
A20: 3 | B20: Matéria-prima da joia | D20: =IF(C20="","",IF(C20=Gabarito!C20,"✔","✗"))
A21: 4 | B21: Aluguel do escritório administrativo | D21: =IF(C21="","",IF(C21=Gabarito!C21,"✔","✗"))
A22: 5 | B22: Salário do professor da FGV (pra FGV) | D22: =IF(C22="","",IF(C22=Gabarito!C22,"✔","✗"))
A23: 6 | B23: Frete pra entregar produto vendido | D23: =IF(C23="","",IF(C23=Gabarito!C23,"✔","✗"))
A24: 7 | B24: Energia elétrica da linha de produção | D24: =IF(C24="","",IF(C24=Gabarito!C24,"✔","✗"))
C25: Acertos: | D25: =COUNTIF(D18:D24,"✔")&" / 7" -> 0 / 7
B27: B3. Qual atividade da DFC?
A28: # | B28: Item | C28: Resposta | D28: Check
A29: 0 | B29: Compra de uma máquina nova | D29: =IF(C29="","",IF(C29=Gabarito!C29,"✔","✗"))
A30: 1 | B30: Recebimento de clientes | D30: =IF(C30="","",IF(C30=Gabarito!C30,"✔","✗"))
A31: 2 | B31: Captação de empréstimo bancário | D31: =IF(C31="","",IF(C31=Gabarito!C31,"✔","✗"))
A32: 3 | B32: Pagamento de dividendos | D32: =IF(C32="","",IF(C32=Gabarito!C32,"✔","✗"))
A33: 4 | B33: Venda de um galpão antigo | D33: =IF(C33="","",IF(C33=Gabarito!C33,"✔","✗"))
A34: 5 | B34: Pagamento a fornecedores | D34: =IF(C34="","",IF(C34=Gabarito!C34,"✔","✗"))
A35: 6 | B35: Recompra de ações | D35: =IF(C35="","",IF(C35=Gabarito!C35,"✔","✗"))
A36: 7 | B36: Aquisição de uma empresa concorrente | D36: =IF(C36="","",IF(C36=Gabarito!C36,"✔","✗"))
C37: Acertos: | D37: =COUNTIF(D30:D36,"✔")&" / 7" -> 0 / 7

Sheet C_Caso1
B1: Mini-caso: Bicicletaria Serra SA (comércio)
B2: Valores em milhares. Despesas e saídas de caixa entram NEGATIVAS nas tuas respostas.
B4: Dados do caso (não mexe) | C4: Valor
B5: Receita líquida | C5: 1000
B6: Mercadoria vendida (CMV) | C6: 600
B7: Despesas de vendas | C7: 120
B8: Despesas administrativas | C8: 80
B9: D&A já embutida nas despesas acima | C9: 30
B10: Despesas financeiras | C10: 40
B11: Receitas financeiras | C11: 10
B12: Alíquota de IR | C12: 0.3
B13: Variação de contas a receber no ano | C13: 50
B14: Variação de estoques no ano | C14: 40
B15: Variação de fornecedores no ano | C15: 20
B16: Compra de imobilizado (capex) | C16: 100
... B20: Caixa no início do ano | C20: 41
B22: C1. Monte a DRE completa
B23: Linha | C23: Seu valor | D23: Check
B24: Receita líquida | D24: =IF(C24="","",IF(ABS(C24-Gabarito!$E$3)<0.5,"✔","✗"))
B25: (-) CMV | D25: =IF(C25="","",IF(ABS(C25-Gabarito!$E$4)<0.5,"✔","✗"))
B26: =lucro bruto -> #VALUE! | D26: =IF(C26="","",IF(ABS(C26-Gabarito!$E$5)<0.5,"✔","✗"))
B27: (-) Despesas de vendas | D27: =IF(C27="","",IF(ABS(C27-Gabarito!$E$6)<0.5,"✔","✗"))
B28: (-) Despesas administrativas | D28: =IF(C28="","",IF(ABS(C28-Gabarito!$E$7)<0.5,"✔","✗"))
B29: =ebit -> #NAME? | D29: =IF(C29="","",IF(ABS(C29-Gabarito!$E$8)<0.5,"✔","✗"))
B30: (+/-) Resultado financeiro | D30: =IF(C30="","",IF(ABS(C30-Gabarito!$E$9)<0.5,"✔","✗"))
B31: =lair -> #NAME? | D31: =IF(C31="","",IF(ABS(C31-Gabarito!$E$10)<0.5,"✔","✗"))
B32: (-) IR | D32: =IF(C32="","",IF(ABS(C32-Gabarito!$E$11)<0.5,"✔","✗"))
B33: =lucro líquido -> #VALUE! | D33: =IF(C33="","",IF(ABS(C33-Gabarito!$E$12)<0.5,"✔","✗"))
B35: C2. Margem bruta (em %)
B36: Linha | C36: Seu valor | D36: Check
B37: Margem bruta | D37: =IF(C37="","",IF(ABS(C37-Gabarito!$E$13)<0.005,"✔","✗"))
B39: C3. FCO pelo método indireto
B40: Linha | C40: Seu valor | D40: Check
B41: Lucro líquido | D41: =IF(C41="","",IF(ABS(C41-Gabarito!$E$14)<0.5,"✔","✗"))
B42: (+) D&A | D42: =IF(C42="","",IF(ABS(C42-Gabarito!$E$15)<0.5,"✔","✗"))
B43: (-) Aumento de contas a receber | D43: =IF(C43="","",IF(ABS(C43-Gabarito!$E$16)<0.5,"✔","✗"))
B44: (-) Aumento de estoques | D44: =IF(C44="","",IF(ABS(C44-Gabarito!$E$17)<0.5,"✔","✗"))
B45: (+) Aumento de fornecedores | D45: =IF(C45="","",IF(ABS(C45-Gabarito!$E$18)<0.5,"✔","✗"))
B46: =fco -> #NAME? | D46: =IF(C46="","",IF(ABS(C46-Gabarito!$E$19)<0.5,"✔","✗"))
B48: C4. DFC completa
...

Sheet C_Caso2
B1: Mini-caso: Livraria Alameda SA (comércio), números novos
B2: Valores em milhares. Despesas e saídas de caixa entram NEGATIVAS nas tuas respostas.
B4: Dados do caso (não mexe) | C4: Valor
B5: Receita líquida | C5: 1200
B6: Mercadoria vendida (CMV) | C6: 660
B7: Despesas de vendas | C7: 150
B8: Despesas administrativas | C8: 90
B9: D&A já embutida nas despesas acima | C9: 40
B10: Despesas financeiras | C10: 60
B11: Receitas financeiras | C11: 20
B12: Alíquota de IR | C12: 0.3
B13: Variação de contas a receber no ano | C13: 80
B14: Variação de estoques no ano | C14: 30
B15: Variação de fornecedores no ano | C15: 50
B16: Compra de imobilizado (capex) | C16: 120
... B20: Caixa no início do ano | C20: 100
B22: C1. Monte a DRE completa
B23: Linha | C23: Seu valor | D23: Check
B24: Receita líquida | D24: =IF(C24="","",IF(ABS(C24-Gabarito!$F$3)<0.5,"✔","✗"))
B25: (-) CMV | D25: =IF(C25="","",IF(ABS(C25-Gabarito!$F$4)<0.5,"✔","✗"))
B26: =lucro bruto -> #VALUE! | D26: =IF(C26="","",IF(ABS(C26-Gabarito!$F$5)<0.5,"✔","✗"))
B27: (-) Despesas de vendas | D27: =IF(C27="","",IF(ABS(C27-Gabarito!$F$6)<0.5,"✔","✗"))
B28: (-) Despesas administrativas | D28: =IF(C28="","",IF(ABS(C28-Gabarito!$F$7)<0.5,"✔","✗"))
B29: =ebit -> #NAME? | D29: =IF(C29="","",IF(ABS(C29-Gabarito!$F$8)<0.5,"✔","✗"))
B30: (+/-) Resultado financeiro | D30: =IF(C30="","",IF(ABS(C30-Gabarito!$F$9)<0.5,"✔","✗"))
B31: =lair -> #NAME? | D31: =IF(C31="","",IF(ABS(C31-Gabarito!$F$10)<0.5,"✔","✗"))
B32: (-) IR | D32: =IF(C32="","",IF(ABS(C32-Gabarito!$F$11)<0.5,"✔","✗"))
B33: =lucro líquido -> #VALUE! | D33: =IF(C33="","",IF(ABS(C33-Gabarito!$F$12)<0.5,"✔","✗"))
B35: C2. Margem bruta (em %)
B36: Linha | C36: Seu valor | D36: Check
B37: Margem bruta | D37: =IF(C37="","",IF(ABS(C37-Gabarito!$F$13)<0.005,"✔","✗"))
B39: C3. FCO pelo método indireto
B40: Linha | C40: Seu valor | D40: Check
B41: Lucro líquido | D41: =IF(C41="","",IF(ABS(C41-Gabarito!$F$14)<0.5,"✔","✗"))
B42: (+) D&A | D42: =IF(C42="","",IF(ABS(C42-Gabarito!$F$15)<0.5,"✔","✗"))
B43: (-) Aumento de contas a receber | D43: =IF(C43="","",IF(ABS(C43-Gabarito!$F$16)<0.5,"✔","✗"))
B44: (-) Aumento de estoques | D44: =IF(C44="","",IF(ABS(C44-Gabarito!$F$17)<0.5,"✔","✗"))
B45: (+) Aumento de fornecedores | D45: =IF(C45="","",IF(ABS(C45-Gabarito!$F$18)<0.5,"✔","✗"))
B46: =fco -> #NAME? | D46: =IF(C46="","",IF(ABS(C46-Gabarito!$F$19)<0.5,"✔","✗"))
B48: C4. DFC completa
...

Sheet D_Pegadinhas
B1: Bloco D: pegadinhas estilo prova
B3: Pergunta | C3: Sua resposta
A4: 1 | B4: O relatório da empresa tem uma linha chamada 'lucro operacional' que vem depois do resultado financeiro. É o EBIT? O que você usa?
A5: 2 | B5: Questão pede 'os investimentos mais relevantes da empresa'. Capital social e reservas de lucros entram na resposta?
A6: 3 | B6: Cervejaria com margem bruta de 45% vs joalheria com 70%. Dá pra concluir que a joalheria agrega mais valor?
A7: 4 | B7: O RA diz 'geração de caixa recorde'. Onde você confere e qual linha específica?
A8: 5 | B8: Empresa comprou máquina de 200 à vista em dezembro. Efeito imediato no lucro do ano? No caixa? Nos lucros dos próximos anos?
